Workbook

Sheet summary
B2: Data | C2: Amount | E2: Sex | F2: Variable | G2: Disease | H2: No Disease | I2: Difference
B3: Total number of patients | C3: 302 | E3: Male | F3: Avg. Age (years) | G3: ='diseased-males'!N22 -> 51.043478 | H3: ='non-diseased_males'!N3 -> 56.087719 | I3: =G3-H3 -> -5.044241
B4: Has heart disease | C4: 164 | F4: Min. Age (years) | G4: =MIN('diseased-males'!P22) -> 29 | H4: ='non-diseased_males'!P3 -> 35 | I4: =G4-H4 -> -6
B5: Doesn't have heart disease | C5: =C3-C4 -> 138 | F5: Max. Age (years) | G5: ='diseased-males'!Q22 -> 70 | H5: ='non-diseased_males'!Q3 -> 77 | I5: =G5-H5 -> -7
B6: Male patients | C6: =COUNTIF(all_patients!C:C, "1") -> 206 | F6: Avg. Resting BP (mmHg) | G6: ='diseased-males'!N23 -> 129.65217 | H6: ='non-diseased_males'!N4 -> 131.92982 | I6: =G6-H6 -> -2.2776506
B7: Female patients | C7: =C3-C6 -> 96 | F7: Min. Resting BP (mmHg) | G7: ='diseased-males'!P23 -> 94 | H7: ='non-diseased_males'!P4 -> 100 | I7: =G7-H7 -> -6
B8: Male patients with heart disease | C8: =diseased_patients!O2 -> 92 | F8: Max. Resting BP (mmHg) | G8: ='diseased-males'!Q23 -> 178 | H8: ='non-diseased_males'!Q4 -> 192 | I8: =G8-H8 -> -14
B9: Female patients with heart disease | C9: =diseased_patients!N2 -> 72 | F9: Avg. Cholesterol (mg/dl) | G9: ='diseased-males'!N24 -> 231.59783 | H9: ='non-diseased_males'!N5 -> 246.0614 | I9: =G9-H9 -> -14.463577
B10: Proportion of male patients with heart disease | C10: =C8/C6 -> 0.44660194 | F10: Min. Cholesterol (mg/dl) | G10: ='diseased-males'!P24 -> 126 | H10: ='non-diseased_males'!P5 -> 131 | I10: =G10-H10 -> -5
B11: Proportion of female patients with heart disease | C11: =C9/C7 -> 0.75 | F11: Max. Cholesterol (mg/dl) | G11: ='diseased-males'!Q24 -> 325 | H11: ='non-diseased_males'!Q5 -> 353 | I11: =G11-H11 -> -28
B12: Male patients without heart disease | C12: =C6-C8 -> 114 | F12: Avg. Max HR (bpm) | G12: ='diseased-males'!N25 -> 161.78261 | H12: ='non-diseased_males'!N6 -> 138.40351 | I12: =G12-H12 -> 23.3791
B13: Female patients without heart disease | C13: =C7-C9 -> 24 | F13: Min. Max HR (bpm) | G13: ='diseased-males'!P25 -> 105 | H13: ='non-diseased_males'!P6 -> 71 | I13: =G13-H13 -> 34
B14: Proportion of male patients without heart disease | C14: =1-C10 -> 0.55339806 | F14: Max. Max HR (bpm) | G14: ='diseased-males'!Q25 -> 202 | H14: ='non-diseased_males'!Q6 -> 195 | I14: =G14-H14 -> 7
B15: Proportion of female patients without heart disease | C15: =1-C11 -> 0.25
B17: Correlations for Patients with Heart Disease | C17: Correlation Coefficient | E17: Sex | F17: Variable | G17: Disease | H17: No Disease | I17: Difference
B18: Age vs. Resting Blood Pressure (Male) | C18: =CORREL('diseased-males'!A:A,'diseased-males'!D:D) -> 0.26634312 | E18: Female | F18: Avg. Age (years) | G18: ='diseased-females'!N22 -> 54.555556 | H18: ='non-diseased_females'!N3 -> 59.041667 | I18: =G18-H18 -> -4.4861111
B19: Age vs. Resting Blood Pressure (Female) | C19: =CORREL('diseased-females'!A:A,'diseased-females'!D:D) -> 0.32072277 | F19: Min. Age (years) | G19: ='diseased-females'!P22 -> 34 | H19: ='non-diseased_females'!P3 -> 43 | I19: =G19-H19 -> -9
B20: Age vs. Cholesterol (Male) | C20: =CORREL('diseased-males'!A:A,'diseased-males'!E:E) -> 0.037698794 | F20: Max. Age (years) | G20: ='diseased-females'!Q22 -> 76 | H20: ='non-diseased_females'!Q3 -> 66 | I20: =G20-H20 -> 10
B21: Age vs. Cholesterol (Female) | C21: =CORREL('diseased-females'!A:A,'diseased-females'!E:E) -> 0.32962473 | F21: Avg. Resting BP (mmHg) | G21: ='diseased-females'!N23 -> 128.73611 | H21: ='non-diseased_females'!N4 -> 146.125 | I21: =G21-H21 -> -17.388889
B22: Age vs. Max HR (Male) | C22: =CORREL('diseased-males'!A:A,'diseased-males'!H:H) -> -0.54159551 | F22: Min. Resting BP (mmHg) | G22: ='diseased-females'!P23 -> 94 | H22: ='non-diseased_females'!P4 -> 108 | I22: =G22-H22 -> -14
B23: Age vs. Max HR (Female) | C23: =CORREL('diseased-females'!A:A,'diseased-females'!H:H) -> -0.46978174 | F23: Max. Resting BP (mmHg) | G23: ='diseased-females'!Q23 -> 180 | H23: ='non-diseased_females'!Q4 -> 200 | I23: =G23-H23 -> -20
F24: Avg. Cholesterol (mg/dl) | G24: ='diseased-females'!N24 -> 256.75 | H24: ='non-diseased_females'!N5 -> 274.95833 | I24: =G24-H24 -> -18.208333
F25: Min. Cholesterol (mg/dl) | G25: ='diseased-females'!P24 -> 141 | H25: ='non-diseased_females'!P5 -> 164 | I25: =G25-H25 -> -23
F26: Max. Cholesterol (mg/dl) | G26: ='diseased-females'!Q24 -> 564 | H26: ='non-diseased_females'!Q5 -> 409 | I26: =G26-H26 -> 155
F27: Avg. Max HR (bpm) | G27: ='diseased-females'!N25 -> 154.02778 | H27: ='non-diseased_females'!N6 -> 142.41667 | I27: =G27-H27 -> 11.611111
F28: Min. Max HR (bpm) | G28: ='diseased-females'!P25 -> 96 | H28: ='non-diseased_females'!P6 -> 97 | I28: =G28-H28 -> -1
F29: Max. Max HR (bpm) | G29: ='diseased-females'!Q25 -> 192 | H29: ='non-diseased_females'!Q6 -> 174 | I29: =G29-H29 -> 18

Sheet pivot
A2: cpt | B2: (All)
A3: target | B3: (All)
A4: restecg | B4: (All)
A6: Row Labels | B6: Average chol | C6: Average maxhr | D6: Average restbps | E6: Average age
A7: Female | B7: 261.30208 | C7: 151.125 | D7: 133.08333 | E7: 55.677083
A8: Male | B8: 239.60194 | C8: 148.84466 | D8: 130.91262 | E8: 53.834951
A9: Grand Total | B9: 246.5 | C9: 149.56954 | D9: 131.60265 | E9: 54.42053
A11: Has disease? | B11: No. of Patients | C11: % of total
A12: No | B12: 0.45695364 | C12: 0.45695364
A13: Yes | B13: 0.54304636 | C13: 0.54304636
A14: Grand Total | B14: 1 | C14: 1
A16: Count of Diseased | B16: Sex
A17: Age Group | B17: Diseased Females | C17: Diseased Males | D17: Total Diseased
A18: 20-29 | B18: 0 | C18: 0.0048543689 | D18: 0.0033112583
A19: 30-39 | B19: 0.052083333 | C19: 0.04368932 | D19: 0.046357616
A20: 40-49 | B20: 0.19791667 | C20: 0.25728155 | D20: 0.2384106
A21: 50-59 | B21: 0.35416667 | C21: 0.44174757 | D21: 0.41390728
A22: 60-69 | B22: 0.34375 | C22: 0.22815534 | D22: 0.26490066
A23: 70+ | B23: 0.052083333 | C23: 0.024271845 | D23: 0.033112583
A24: Total Diseased | B24: 1 | C24: 1 | D24: 1

Sheet data_quality
B2: Check | C2: Result
B3: Number of records | C3: 1025
B4: Duplicate records | C4: 723
B5: Missing values | C5: 0
B6: Invalid age values | C6: 0
B7: Invalid cholesterol values | C7: 0
B8: Invalid caterogical values | C8: 0
B9: Numeric columns stored as text | C9: 0
B12: Cleaning perfomed

Sheet categorical_analysis
B2: General Heart Disease Prevalence
B3: Status | C3: Total Patients | D3: Prevalence
B4: Has heart diease | C4: =summary!C4 -> 164 | D4: =C4/summary!C3 -> 0.54304636
B5: Doesn't have heart disease | C5: =summary!C5 -> 138 | D5: =C5/summary!C3 -> 0.45695364
B13: Heart Disease Prevalence By Age
B14: Age Group | C14: Total Patients | D14: Diseased | E14: Prevalence
B15: 20-29 | C15: =COUNTIF(all_patients!A:A, "<30") -> 1 | D15: =COUNTIF(diseased_patients!A:A, "<30") -> 1 | E15: =D15/C15 -> 1
B16: 30-39 | C16: =COUNTIFS(all_patients!A:A,">=30",all_patients!A:A,"<40") -> 14 | D16: =COUNTIFS(diseased_patients!A:A,">=30",diseased_patients!A:A,"<40") -> 10 | E16: =D16/C16 -> 0.71428571
B17: 40-49 | C17: =COUNTIFS(all_patients!A:A,">=40",all_patients!A:A,"<50") -> 72 | D17: =COUNTIFS(diseased_patients!A:A,">=40",diseased_patients!A:A,"<50") -> 50 | E17: =D17/C17 -> 0.69444444
B18: 50-59 | C18: =COUNTIFS(all_patients!A:A,">=50",all_patients!A:A,"<60") -> 125 | D18: =COUNTIFS(diseased_patients!A:A,">=50",diseased_patients!A:A,"<60") -> 65 | E18: =D18/C18 -> 0.52
B19: 60-69 | C19: =COUNTIFS(all_patients!A:A,">=60",all_patients!A:A,"<70") -> 80 | D19: =COUNTIFS(diseased_patients!A:A,">=60",diseased_patients!A:A,"<70") -> 32 | E19: =D19/C19 -> 0.4
B20: 70+ | C20: =COUNTIF(all_patients!A:A,">=70") -> 10 | D20: =COUNTIF(diseased_patients!A:A, ">=70") -> 6 | E20: =D20/C20 -> 0.6
B24: Heart Disease Prevalence by Sex
B25: Sex | C25: Total Patients | D25: Diseased | E25: Prevalence
B26: Male | C26: =COUNTIF(all_patients!C:C,"1") -> 206 | D26: =COUNTIF(diseased_patients!C:C,"1") -> 92 | E26: =D26/C26 -> 0.44660194
B27: Female | C27: =COUNTIF(all_patients!C:C,"0") -> 96 | D27: =COUNTIF(diseased_patients!C:C,"0") -> 72 | E27: =D27/C27 -> 0.75
B35: Heart Disease Prevalence by Chest Pain Type
B36: Chest Pain Type | C36: Patients | D36: Diseased | E36: Prevalence
B37: Typical Angina | C37: =COUNTIF(all_patients!D:D, "0") -> 143 | D37: =COUNTIF(diseased_patients!D:D, "0") -> 39 | E37: =D37/C37 -> 0.27272727
B38: Atypical Angina | C38: =COUNTIF(all_patients!D:D, "1") -> 50 | D38: =COUNTIF(diseased_patients!D:D, "1") -> 41 | E38: =D38/C38 -> 0.82
B39: Non-anginal | C39: =COUNTIF(all_patients!D:D, "2") -> 86 | D39: =COUNTIF(diseased_patients!D:D, "2") -> 68 | E39: =D39/C39 -> 0.79069767
B40: Asymptomatic | C40: =COUNTIF(all_patients!D:D, "3") -> 23 | D40: =COUNTIF(diseased_patients!D:D, "3") -> 16 | E40: =D40/C40 -> 0.69565217
B48: Heart Disease Prevalence by Resting Blood Pressure
B49: Resting Blood Pressure Range | C49: Patients | D49: Diseased | E49: Prevalence
B50: <100 | C50: =restbps!M3 -> 2 | D50: =restbps!J3 -> 2 | E50: =D50/C50 -> 1
B51: 100-119 | C51: =restbps!M4 -> 58 | D51: =restbps!J4 -> 35 | E51: =D51/C51 -> 0.60344828
B52: 120-139 | C52: =restbps!M5 -> 145 | D52: =restbps!J5 -> 83 | E52: =D52/C52 -> 0.57241379
B53: 140-159 | C53: =restbps!M6 -> 71 | D53: =restbps!J6 -> 35 | E53: =D53/C53 -> 0.49295775
B54: 160-179 | C54: =restbps!M7 -> 21 | D54: =restbps!J7 -> 8 | E54: =D54/C54 -> 0.38095238
B55: 180+ | C55: =restbps!M8 -> 4 | D55: =restbps!J8 -> 1 | E55: =D55/C55 -> 0.25
B58: Heart Disease Prevalence by Cholesterol
B59: Cholesterol Range | C59: Patients | D59: Diseased | E59: Prevalence
B60: 100-149 | C60: 1 | D60: =cholesterol!J3 -> 3 | E60: =D60/C60 -> 3
B61: 150-199 | C61: 1 | D61: =cholesterol!J4 -> 26 | E61: =D61/C61 -> 26
B62: 200-249 | C62: 1 | D62: =cholesterol!J5 -> 74 | E62: =D62/C62 -> 74
B63: 250-299 | C63: 1 | D63: =cholesterol!J6 -> 38 | E63: =D63/C63 -> 38
B64: 300-349 | C64: 1 | D64: =cholesterol!J7 -> 18 | E64: =D64/C64 -> 18
B65: 350-399 | C65: 1 | D65: =cholesterol!J8 -> 3 | E65: =D65/C65 -> 3
B66: 400+ | C66: 1 | D66: =cholesterol!J9 -> 2 | E66: =D66/C66 -> 2
B69: Heart Disease Prevalence by Fasting Blood Sugar
...

Sheet restbps
A1: Diseased Males | D1: Diseased Females | G1: Counts | H1: Diseased | K1: Total Patients | O1: Non-diseased Males | R1: Non-diseased Females
A2: age | B2: restbps | D2: age | E2: restbps | G2: Bins | H2: Males | I2: Females | J2: Total | K2: Males | L2: Females | M2: Total | O2: age | P2: restbps | R2: age | S2: restbps
A3: 58 | B3: 140 | D3: 58 | E3: 100 | G3: <100 | H3: =COUNTIF(B:B,"<100") -> 1 | I3: =COUNTIF(E:E,"<100") -> 1 | J3: =H3+I3 -> 2 | K3: =COUNTIF(P:P,"<100")+H3 -> 1 | L3: =COUNTIF(S:S,"<100")+I3 -> 1 | M3: =K3+L3 -> 2 | O3: 55 | P3: 132 | R3: 56 | S3: 134
A4: 45 | B4: 104 | D4: 71 | E4: 112 | G4: 100-119 | H4: =COUNTIFS(B:B,">=100",B:B,"<120") -> 18 | I4: =COUNTIFS(E:E,">=100",E:E,"<120") -> 17 | J4: =H4+I4 -> 35 | K4: =COUNTIFS(P:P,">=100",P:P,"<120")+H4 -> 40 | L4: =COUNTIFS(S:S,">=100",S:S,"<120")+I4 -> 18 | M4: =K4+L4 -> 58 | O4: 57 | P4: 110 | R4: 63 | S4: 150
A5: 44 | B5: 130 | D5: 34 | E5: 118 | G5: 120-139 | H5: =COUNTIFS(B:B,">=120",B:B,"<140") -> 48 | I5: =COUNTIFS(E:E,">=120",E:E,"<140") -> 35 | J5: =H5+I5 -> 83 | K5: =COUNTIFS(P:P,">=120",P:P,"<140")+H5 -> 100 | L5: =COUNTIFS(S:S,">=120",S:S,"<140")+I5 -> 45 | M5: =K5+L5 -> 145 | O5: 64 | P5: 140 | R5: 43 | S5: 132
A6: 50 | B6: 129 | D6: 51 | E6: 140 | G6: 140-159 | H6: =COUNTIFS(B:B,">=140",B:B,"<160") -> 20 | I6: =COUNTIFS(E:E,">=140",E:E,"<160") -> 15 | J6: =H6+I6 -> 35 | K6: =COUNTIFS(P:P,">=140",P:P,"<160")+H6 -> 49 | L6: =COUNTIFS(S:S,">=140",S:S,"<160")+I6 -> 22 | M6: =K6+L6 -> 71 | O6: 63 | P6: 130 | R6: 61 | S6: 130
A7: 51 | B7: 125 | D7: 50 | E7: 120 | G7: 160-179 | H7: =COUNTIFS(B:B,">=160",B:B,"<180") -> 5 | I7: =COUNTIFS(E:E,">=160",E:E,"<180") -> 3 | J7: =H7+I7 -> 8 | K7: =COUNTIFS(P:P,">=160",P:P,"<180")+H7 -> 14 | L7: =COUNTIFS(S:S,">=160",S:S,"<180")+I7 -> 7 | M7: =K7+L7 -> 21 | O7: 59 | P7: 170 | R7: 55 | S7: 180
A8: 59 | B8: 138 | D8: 67 | E8: 106 | G8: 180+ | H8: =COUNTIFS(B:B,">=180") -> 0 | I8: =COUNTIFS(E:E,">=180") -> 1 | J8: =H8+I8 -> 1 | K8: =COUNTIFS(E:E,">=180")+H8 -> 1 | L8: =COUNTIFS(S:S,">=180")+I8 -> 3 | M8: =K8+L8 -> 4 | O8: 70 | P8: 130 | R8: 58 | S8: 136
A9: 64 | B9: 128 | D9: 63 | E9: 135 | O9: 58 | P9: 114 | R9: 61 | S9: 145
A10: 54 | B10: 120 | D10: 42 | E10: 120 | O10: 42 | P10: 136 | R10: 51 | S10: 130
A11: 42 | B11: 140 | D11: 65 | E11: 160 | O11: 46 | P11: 140 | R11: 62 | S11: 138
A12: 41 | B12: 135 | D12: 55 | E12: 132 | O12: 64 | P12: 125 | R12: 56 | S12: 200
A13: 38 | B13: 138 | D13: 66 | E13: 146 | O13: 45 | P13: 142 | R13: 63 | S13: 108
A14: 56 | B14: 120 | D14: 58 | E14: 150 | O14: 77 | P14: 125 | R14: 62 | S14: 140
A15: 48 | B15: 130 | D15: 37 | E15: 120 | O15: 58 | P15: 125 | R15: 62 | S15: 130
A16: 29 | B16: 130 | D16: 54 | E16: 108 | O16: 67 | P16: 100 | R16: 60 | S16: 150
A17: 59 | B17: 150 | D17: 62 | E17: 124 | O17: 51 | P17: 140 | R17: 59 | S17: 174
A18: 53 | B18: 130 | D18: 45 | E18: 138 | O18: 51 | P18: 140 | R18: 62 | S18: 150
A19: 47 | B19: 138 | D19: 57 | E19: 128 | O19: 60 | P19: 140 | R19: 57 | S19: 140
A20: 48 | B20: 124 | D20: 76 | E20: 140 | O20: 44 | P20: 112 | R20: 57 | S20: 130
... A26: 44 | B26: 120 | D26: 65 | E26: 140 | O26: 58 | P26: 120 | R26: 62 | S26: 160
A27: 52 | B27: 108 | D27: 60 | E27: 150 | O27: 54 | P27: 192
A28: 42 | B28: 120 | D28: 51 | E28: 130 | O28: 56 | P28: 130
A29: 45 | B29: 128 | D29: 64 | E29: 180 | O29: 53 | P29: 123
A30: 57 | B30: 150 | D30: 51 | E30: 120 | O30: 65 | P30: 138
A31: 47 | B31: 112 | D31: 57 | E31: 120 | O31: 60 | P31: 145
A32: 59 | B32: 140 | D32: 45 | E32: 112 | O32: 35 | P32: 126
A33: 54 | B33: 108 | D33: 39 | E33: 94 | O33: 62 | P33: 120
A34: 52 | B34: 118 | D34: 60 | E34: 102 | O34: 57 | P34: 150
A35: 53 | B35: 142 | D35: 44 | E35: 118 | O35: 47 | P35: 110
A36: 66 | B36: 120 | D36: 41 | E36: 126 | O36: 57 | P36: 152
A37: 52 | B37: 138 | D37: 49 | E37: 130 | O37: 48 | P37: 124
A38: 57 | B38: 140 | D38: 54 | E38: 132 | O38: 68 | P38: 180
... A74: 54 | B74: 125 | D74: 68 | E74: 120 | O74: 60 | P74: 117
A75: 52 | B75: 172 | O75: 58 | P75: 112
A76: 57 | B76: 110 | O76: 52 | P76: 112
A77: 53 | B77: 130 | O77: 57 | P77: 128
A78: 58 | B78: 105 | O78: 48 | P78: 110
A79: 51 | B79: 110 | O79: 67 | P79: 120
A80: 63 | B80: 145 | O80: 58 | P80: 132
...

Sheet cholesterol
A1: Males | D1: Females | G1: Counts | H1: Diseased | K1: Total Patients
A2: age | B2: chol | D2: age | E2: chol | G2: Bins | H2: Males | I2: Females | J2: Total | K2: Males | L2: Females | M2: Total
A3: 58 | B3: 211 | D3: 58 | E3: 248 | G3: 100-149 | H3: =COUNTIF(B:B,"<150") -> 1 | I3: =COUNTIF(E:E,"<150") -> 2 | J3: =H3+I3 -> 3 | M3: =K3+L3 -> 0
A4: 45 | B4: 208 | D4: 71 | E4: 149 | G4: 150-199 | H4: =COUNTIFS(B:B,">=150",B:B,"<200") -> 16 | I4: =COUNTIFS(E:E,">=150",E:E,"<200") -> 10 | J4: =H4+I4 -> 26 | M4: =K4+L4 -> 0
A5: 44 | B5: 233 | D5: 34 | E5: 210 | G5: 200-249 | H5: =COUNTIFS(B:B,">=200",B:B,"<250") -> 50 | I5: =COUNTIFS(E:E,">=200",E:E,"<250") -> 24 | J5: =H5+I5 -> 74 | M5: =K5+L5 -> 0
A6: 50 | B6: 196 | D6: 51 | E6: 308 | G6: 250-299 | H6: =COUNTIFS(B:B,">=250",B:B,"<300") -> 18 | I6: =COUNTIFS(E:E,">=250",E:E,"<300") -> 20 | J6: =H6+I6 -> 38 | M6: =K6+L6 -> 0
A7: 51 | B7: 213 | D7: 50 | E7: 244 | G7: 300-349 | H7: =COUNTIFS(B:B,">=300",B:B,"<350") -> 7 | I7: =COUNTIFS(E:E,">=300",E:E,"<350") -> 11 | J7: =H7+I7 -> 18 | M7: =K7+L7 -> 0
A8: 59 | B8: 271 | D8: 67 | E8: 223 | G8: 350-399 | H8: =COUNTIFS(B:B,">=350",B:B,"<400") -> 0 | I8: =COUNTIFS(E:E,">=350",E:E,"<400") -> 3 | J8: =H8+I8 -> 3 | M8: =K8+L8 -> 0
A9: 64 | B9: 263 | D9: 63 | E9: 252 | G9: 400+ | H9: =COUNTIFS(B:B,">=400") -> 0 | I9: =COUNTIFS(E:E,">=400") -> 2 | J9: =H9+I9 -> 2 | M9: =K9+L9 -> 0
A10: 54 | B10: 258 | D10: 42 | E10: 209
A11: 42 | B11: 226 | D11: 65 | E11: 360
A12: 41 | B12: 203 | D12: 55 | E12: 342
A13: 38 | B13: 175 | D13: 66 | E13: 278
A14: 56 | B14: 193 | D14: 58 | E14: 283
A15: 48 | B15: 245 | D15: 37 | E15: 215
A16: 29 | B16: 204 | D16: 54 | E16: 267
A17: 59 | B17: 212 | D17: 62 | E17: 209
A18: 53 | B18: 197 | D18: 45 | E18: 236
A19: 47 | B19: 257 | D19: 57 | E19: 303
A20: 48 | B20: 255 | D20: 76 | E20: 197
A21: 52 | B21: 201 | D21: 43 | E21: 213
... A74: 54 | B74: 273 | D74: 68 | E74: 211
A75: 52 | B75: 199
A76: 57 | B76: 201
A77: 53 | B77: 246
A78: 58 | B78: 240
A79: 51 | B79: 175
A80: 63 | B80: 233
A81: 70 | B81: 245
A82: 57 | B82: 168
A83: 47 | B83: 253
A84: 41 | B84: 214
A85: 59 | B85: 234
A86: 54 | B86: 239
... A94: 65 | B94: 177

Sheet maxhr
A1: Male | D1: Females | G1: Counts | H1: Diseased | K1: Total Patients
A2: age | B2: maxhr | D2: age | E2: maxhr | G2: Bins | H2: Males | I2: Females | J2: Total | K2: Males | L2: Females | M2: Total
A3: 58 | B3: 165 | D3: 58 | E3: 122 | G3: <100 | H3: =COUNTIF(B:B,"<100") -> 0 | I3: =COUNTIF(E:E,"<100") -> 1 | J3: =H3+I3 -> 1 | M3: =K3+L3 -> 0
A4: 45 | B4: 148 | D4: 71 | E4: 125 | G4: 100-119 | H4: =COUNTIFS(B:B,">=100",B:B,"<120") -> 2 | I4: =COUNTIFS(E:E,">=100",E:E,"<120") -> 4 | J4: =H4+I4 -> 6 | M4: =K4+L4 -> 0
A5: 44 | B5: 179 | D5: 34 | E5: 192 | G5: 120-139 | H5: =COUNTIFS(B:B,">=120",B:B,"<140") -> 7 | I5: =COUNTIFS(E:E,">=120",E:E,"<140") -> 10 | J5: =H5+I5 -> 17 | M5: =K5+L5 -> 0
A6: 50 | B6: 163 | D6: 51 | E6: 142 | G6: 140-159 | H6: =COUNTIFS(B:B,">=140",B:B,"<160") -> 29 | I6: =COUNTIFS(E:E,">=140",E:E,"<160") -> 22 | J6: =H6+I6 -> 51 | M6: =K6+L6 -> 0
A7: 51 | B7: 125 | D7: 50 | E7: 162 | G7: 160-179 | H7: =COUNTIFS(B:B,">=160",B:B,"<180") -> 39 | I7: =COUNTIFS(E:E,">=160",E:E,"<180") -> 33 | J7: =H7+I7 -> 72 | M7: =K7+L7 -> 0
A8: 59 | B8: 182 | D8: 67 | E8: 142 | G8: 180+ | H8: =COUNTIF(B:B,">=180") -> 15 | I8: =COUNTIF(E:E,">=180") -> 2 | J8: =H8+I8 -> 17 | M8: =K8+L8 -> 0
A9: 64 | B9: 105 | D9: 63 | E9: 172
A10: 54 | B10: 147 | D10: 42 | E10: 173
A11: 42 | B11: 178 | D11: 65 | E11: 151
A12: 41 | B12: 132 | D12: 55 | E12: 166
A13: 38 | B13: 173 | D13: 66 | E13: 152
A14: 56 | B14: 162 | D14: 58 | E14: 162
A15: 48 | B15: 180 | D15: 37 | E15: 170
A16: 29 | B16: 202 | D16: 54 | E16: 167
A17: 59 | B17: 157 | D17: 62 | E17: 163
A18: 53 | B18: 152 | D18: 45 | E18: 152
A19: 47 | B19: 156 | D19: 57 | E19: 159
A20: 48 | B20: 175 | D20: 76 | E20: 116
... A74: 54 | B74: 152 | D74: 68 | E74: 115
A75: 52 | B75: 162
A76: 57 | B76: 126
A77: 53 | B77: 173
A78: 58 | B78: 154
A79: 51 | B79: 123
A80: 63 | B80: 150
A81: 70 | B81: 143
A82: 57 | B82: 174
A83: 47 | B83: 179
A84: 41 | B84: 168
A85: 59 | B85: 161
A86: 54 | B86: 160
... A94: 65 | B94: 140

Sheet all_patients
A1: age | B1: agegroup | C1: sex | D1: cpt | E1: restbps | F1: chol | G1: fbs | H1: restecg | I1: maxhr | J1: exang | K1: slope | L1: thal | M1: target
A2: 67 | B2: =IF(A2<30,"20-29",IF(A2<40,"30-39",IF(A2<50,"40-49",IF(A2<60,"50-59",IF(A2<70,"60-69",IF(A2<80,"70+")))))) -> 60-69 | C2: 0 | D2: 2 | E2: 115 | F2: 564 | G2: 0 | H2: 0 | I2: 160 | J2: 0 | K2: 1 | L2: 3 | M2: 1
A3: 65 | B3: =IF(A3<30,"20-29",IF(A3<40,"30-39",IF(A3<50,"40-49",IF(A3<60,"50-59",IF(A3<70,"60-69",IF(A3<80,"70+")))))) -> 60-69 | C3: 0 | D3: 2 | E3: 140 | F3: 417 | G3: 1 | H3: 0 | I3: 157 | J3: 0 | K3: 2 | L3: 2 | M3: 1
A4: 56 | B4: =IF(A4<30,"20-29",IF(A4<40,"30-39",IF(A4<50,"40-49",IF(A4<60,"50-59",IF(A4<70,"60-69",IF(A4<80,"70+")))))) -> 50-59 | C4: 0 | D4: 0 | E4: 134 | F4: 409 | G4: 0 | H4: 0 | I4: 150 | J4: 1 | K4: 1 | L4: 3 | M4: 0
A5: 63 | B5: =IF(A5<30,"20-29",IF(A5<40,"30-39",IF(A5<50,"40-49",IF(A5<60,"50-59",IF(A5<70,"60-69",IF(A5<80,"70+")))))) -> 60-69 | C5: 0 | D5: 0 | E5: 150 | F5: 407 | G5: 0 | H5: 0 | I5: 154 | J5: 0 | K5: 1 | L5: 3 | M5: 0
A6: 62 | B6: =IF(A6<30,"20-29",IF(A6<40,"30-39",IF(A6<50,"40-49",IF(A6<60,"50-59",IF(A6<70,"60-69",IF(A6<80,"70+")))))) -> 60-69 | C6: 0 | D6: 0 | E6: 140 | F6: 394 | G6: 0 | H6: 0 | I6: 157 | J6: 0 | K6: 1 | L6: 2 | M6: 1
A7: 65 | B7: =IF(A7<30,"20-29",IF(A7<40,"30-39",IF(A7<50,"40-49",IF(A7<60,"50-59",IF(A7<70,"60-69",IF(A7<80,"70+")))))) -> 60-69 | C7: 0 | D7: 2 | E7: 160 | F7: 360 | G7: 0 | H7: 0 | I7: 151 | J7: 0 | K7: 2 | L7: 2 | M7: 1
A8: 57 | B8: =IF(A8<30,"20-29",IF(A8<40,"30-39",IF(A8<50,"40-49",IF(A8<60,"50-59",IF(A8<70,"60-69",IF(A8<80,"70+")))))) -> 50-59 | C8: 0 | D8: 0 | E8: 120 | F8: 354 | G8: 0 | H8: 1 | I8: 163 | J8: 1 | K8: 2 | L8: 2 | M8: 1
A9: 55 | B9: =IF(A9<30,"20-29",IF(A9<40,"30-39",IF(A9<50,"40-49",IF(A9<60,"50-59",IF(A9<70,"60-69",IF(A9<80,"70+")))))) -> 50-59 | C9: 1 | D9: 0 | E9: 132 | F9: 353 | G9: 0 | H9: 1 | I9: 132 | J9: 1 | K9: 1 | L9: 3 | M9: 0
A10: 55 | B10: =IF(A10<30,"20-29",IF(A10<40,"30-39",IF(A10<50,"40-49",IF(A10<60,"50-59",IF(A10<70,"60-69",IF(A10<80,"70+")))))) -> 50-59 | C10: 0 | D10: 1 | E10: 132 | F10: 342 | G10: 0 | H10: 1 | I10: 166 | J10: 0 | K10: 2 | L10: 2 | M10: 1
A11: 43 | B11: =IF(A11<30,"20-29",IF(A11<40,"30-39",IF(A11<50,"40-49",IF(A11<60,"50-59",IF(A11<70,"60-69",IF(A11<80,"70+")))))) -> 40-49 | C11: 0 | D11: 0 | E11: 132 | F11: 341 | G11: 1 | H11: 0 | I11: 136 | J11: 1 | K11: 1 | L11: 3 | M11: 0
A12: 58 | B12: =IF(A12<30,"20-29",IF(A12<40,"30-39",IF(A12<50,"40-49",IF(A12<60,"50-59",IF(A12<70,"60-69",IF(A12<80,"70+")))))) -> 50-59 | C12: 0 | D12: 2 | E12: 120 | F12: 340 | G12: 0 | H12: 1 | I12: 172 | J12: 0 | K12: 2 | L12: 2 | M12: 1
A13: 57 | B13: =IF(A13<30,"20-29",IF(A13<40,"30-39",IF(A13<50,"40-49",IF(A13<60,"50-59",IF(A13<70,"60-69",IF(A13<80,"70+")))))) -> 50-59 | C13: 1 | D13: 0 | E13: 110 | F13: 335 | G13: 0 | H13: 1 | I13: 143 | J13: 1 | K13: 1 | L13: 3 | M13: 0
... A303: 57 | B303: =IF(A303<30,"20-29",IF(A303<40,"30-39",IF(A303<50,"40-49",IF(A303<60,"50-59",IF(A303<70,"60-69",IF(A303<80,"70+")))))) -> 50-59 | C303: 1 | D303: 2 | E303: 150 | F303: 126 | G303: 1 | H303: 1 | I303: 173 | J303: 0 | K303: 2 | L303: 3 | M303: 1

Sheet diseased_patients
A1: age | B1: agegroup | C1: sex | D1: cpt | E1: restbps | F1: chol | G1: fbs | H1: restecg | I1: maxhr | J1: exang | K1: slope | L1: thal | N1: females | O1: males
A2: 64 | B2: =IF(A2<30,"20-29",IF(A2<40,"30-39",IF(A2<50,"40-49",IF(A2<60,"50-59",IF(A2<70,"60-69",IF(A2<80,"70+")))))) -> 60-69 | C2: 0 | D2: 0 | E2: 180 | F2: 325 | G2: 0 | H2: 1 | I2: 154 | J2: 1 | K2: 2 | L2: 2 | N2: =COUNTIF(C2:C527, "0") -> 72 | O2: =COUNTIF(C2:C165, "1") -> 92
A3: 59 | B3: =IF(A3<30,"20-29",IF(A3<40,"30-39",IF(A3<50,"40-49",IF(A3<60,"50-59",IF(A3<70,"60-69",IF(A3<80,"70+")))))) -> 50-59 | C3: 1 | D3: 3 | E3: 178 | F3: 270 | G3: 0 | H3: 0 | I3: 145 | J3: 0 | K3: 0 | L3: 3
A4: 52 | B4: =IF(A4<30,"20-29",IF(A4<40,"30-39",IF(A4<50,"40-49",IF(A4<60,"50-59",IF(A4<70,"60-69",IF(A4<80,"70+")))))) -> 50-59 | C4: 1 | D4: 2 | E4: 172 | F4: 199 | G4: 1 | H4: 1 | I4: 162 | J4: 0 | K4: 2 | L4: 3
A5: 64 | B5: =IF(A5<30,"20-29",IF(A5<40,"30-39",IF(A5<50,"40-49",IF(A5<60,"50-59",IF(A5<70,"60-69",IF(A5<80,"70+")))))) -> 60-69 | C5: 1 | D5: 3 | E5: 170 | F5: 227 | G5: 0 | H5: 0 | I5: 155 | J5: 0 | K5: 1 | L5: 3
A6: 54 | B6: =IF(A6<30,"20-29",IF(A6<40,"30-39",IF(A6<50,"40-49",IF(A6<60,"50-59",IF(A6<70,"60-69",IF(A6<80,"70+")))))) -> 50-59 | C6: 0 | D6: 2 | E6: 160 | F6: 201 | G6: 0 | H6: 1 | I6: 163 | J6: 0 | K6: 2 | L6: 2
A7: 66 | B7: =IF(A7<30,"20-29",IF(A7<40,"30-39",IF(A7<50,"40-49",IF(A7<60,"50-59",IF(A7<70,"60-69",IF(A7<80,"70+")))))) -> 60-69 | C7: 1 | D7: 0 | E7: 160 | F7: 228 | G7: 0 | H7: 0 | I7: 138 | J7: 0 | K7: 2 | L7: 1
A8: 65 | B8: =IF(A8<30,"20-29",IF(A8<40,"30-39",IF(A8<50,"40-49",IF(A8<60,"50-59",IF(A8<70,"60-69",IF(A8<80,"70+")))))) -> 60-69 | C8: 0 | D8: 2 | E8: 160 | F8: 360 | G8: 0 | H8: 0 | I8: 151 | J8: 0 | K8: 2 | L8: 2
A9: 71 | B9: =IF(A9<30,"20-29",IF(A9<40,"30-39",IF(A9<50,"40-49",IF(A9<60,"50-59",IF(A9<70,"60-69",IF(A9<80,"70+")))))) -> 70+ | C9: 0 | D9: 1 | E9: 160 | F9: 302 | G9: 0 | H9: 1 | I9: 162 | J9: 0 | K9: 2 | L9: 2
A10: 69 | B10: =IF(A10<30,"20-29",IF(A10<40,"30-39",IF(A10<50,"40-49",IF(A10<60,"50-59",IF(A10<70,"60-69",IF(A10<80,"70+")))))) -> 60-69 | C10: 1 | D10: 3 | E10: 160 | F10: 234 | G10: 1 | H10: 0 | I10: 131 | J10: 0 | K10: 1 | L10: 2
A11: 70 | B11: =IF(A11<30,"20-29",IF(A11<40,"30-39",IF(A11<50,"40-49",IF(A11<60,"50-59",IF(A11<70,"60-69",IF(A11<80,"70+")))))) -> 70+ | C11: 1 | D11: 1 | E11: 156 | F11: 245 | G11: 0 | H11: 0 | I11: 143 | J11: 0 | K11: 2 | L11: 2
A12: 65 | B12: =IF(A12<30,"20-29",IF(A12<40,"30-39",IF(A12<50,"40-49",IF(A12<60,"50-59",IF(A12<70,"60-69",IF(A12<80,"70+")))))) -> 60-69 | C12: 0 | D12: 2 | E12: 155 | F12: 269 | G12: 0 | H12: 1 | I12: 148 | J12: 0 | K12: 2 | L12: 2
A13: 67 | B13: =IF(A13<30,"20-29",IF(A13<40,"30-39",IF(A13<50,"40-49",IF(A13<60,"50-59",IF(A13<70,"60-69",IF(A13<80,"70+")))))) -> 60-69 | C13: 0 | D13: 2 | E13: 152 | F13: 277 | G13: 0 | H13: 1 | I13: 172 | J13: 0 | K13: 2 | L13: 2
A14: 52 | B14: =IF(A14<30,"20-29",IF(A14<40,"30-39",IF(A14<50,"40-49",IF(A14<60,"50-59",IF(A14<70,"60-69",IF(A14<80,"70+")))))) -> 50-59 | C14: 1 | D14: 3 | E14: 152 | F14: 298 | G14: 1 | H14: 1 | I14: 178 | J14: 0 | K14: 1 | L14: 3
... A165: 39 | B165: =IF(A165<30,"20-29",IF(A165<40,"30-39",IF(A165<50,"40-49",IF(A165<60,"50-59",IF(A165<70,"60-69",IF(A165<80,"70+")))))) -> 30-39 | C165: 0 | D165: 2 | E165: 94 | F165: 199 | G165: 0 | H165: 1 | I165: 179 | J165: 0 | K165: 2 | L165: 2

Sheet non_diseased_patients
A1: age | B1: sex | C1: cpt | D1: restbps | E1: chol | F1: fbs | G1: restecg | H1: maxhr | I1: exang | J1: slope | K1: thal | M1: females | N1: males
A2: 56 | B2: 0 | C2: 0 | D2: 134 | E2: 409 | F2: 0 | G2: 0 | H2: 150 | I2: 1 | J2: 1 | K2: 3 | M2: =COUNTIF(B2:B527, "0") -> 24 | N2: =COUNTIF(B2:B527, "1") -> 114
A3: 63 | B3: 0 | C3: 0 | D3: 150 | E3: 407 | F3: 0 | G3: 0 | H3: 154 | I3: 0 | J3: 1 | K3: 3
A4: 55 | B4: 1 | C4: 0 | D4: 132 | E4: 353 | F4: 0 | G4: 1 | H4: 132 | I4: 1 | J4: 1 | K4: 3
A5: 43 | B5: 0 | C5: 0 | D5: 132 | E5: 341 | F5: 1 | G5: 0 | H5: 136 | I5: 1 | J5: 1 | K5: 3
A6: 57 | B6: 1 | C6: 0 | D6: 110 | E6: 335 | F6: 0 | G6: 1 | H6: 143 | I6: 1 | J6: 1 | K6: 3
A7: 64 | B7: 1 | C7: 2 | D7: 140 | E7: 335 | F7: 0 | G7: 1 | H7: 158 | I7: 0 | J7: 2 | K7: 2
A8: 61 | B8: 0 | C8: 0 | D8: 130 | E8: 330 | F8: 0 | G8: 0 | H8: 169 | I8: 0 | J8: 2 | K8: 2
A9: 63 | B9: 1 | C9: 0 | D9: 130 | E9: 330 | F9: 1 | G9: 0 | H9: 132 | I9: 1 | J9: 2 | K9: 3
A10: 55 | B10: 0 | C10: 0 | D10: 180 | E10: 327 | F10: 0 | G10: 2 | H10: 117 | I10: 1 | J10: 1 | K10: 2
A11: 59 | B11: 1 | C11: 0 | D11: 170 | E11: 326 | F11: 0 | G11: 0 | H11: 140 | I11: 1 | J11: 0 | K11: 3
A12: 70 | B12: 1 | C12: 0 | D12: 130 | E12: 322 | F12: 0 | G12: 0 | H12: 109 | I12: 0 | J12: 1 | K12: 2
A13: 58 | B13: 0 | C13: 1 | D13: 136 | E13: 319 | F13: 1 | G13: 0 | H13: 152 | I13: 0 | J13: 2 | K13: 2
A14: 58 | B14: 1 | C14: 0 | D14: 114 | E14: 318 | F14: 0 | G14: 2 | H14: 140 | I14: 0 | J14: 0 | K14: 1
... A139: 57 | B139: 1 | C139: 0 | D139: 130 | E139: 131 | F139: 0 | G139: 1 | H139: 115 | I139: 1 | J139: 1 | K139: 3

Sheet diseased-males
A1: age | B1: agegroup | C1: cpt | D1: restbps | E1: chol | F1: fbs | G1: restecg | H1: maxhr | I1: exang | J1: slope | K1: thal
A2: 58 | B2: =IF(A2<30,"20-29",IF(A2<40,"30-39",IF(A2<50,"40-49",IF(A2<60,"50-59",IF(A2<70,"60-69",IF(A2<80,"70+")))))) -> 50-59 | C2: 2 | D2: 140 | E2: 211 | F2: 1 | G2: 0 | H2: 165 | I2: 0 | J2: 2 | K2: 2
A3: 45 | B3: =IF(A3<30,"20-29",IF(A3<40,"30-39",IF(A3<50,"40-49",IF(A3<60,"50-59",IF(A3<70,"60-69",IF(A3<80,"70+")))))) -> 40-49 | C3: 0 | D3: 104 | E3: 208 | F3: 0 | G3: 0 | H3: 148 | I3: 1 | J3: 1 | K3: 2
A4: 44 | B4: =IF(A4<30,"20-29",IF(A4<40,"30-39",IF(A4<50,"40-49",IF(A4<60,"50-59",IF(A4<70,"60-69",IF(A4<80,"70+")))))) -> 40-49 | C4: 2 | D4: 130 | E4: 233 | F4: 0 | G4: 1 | H4: 179 | I4: 1 | J4: 2 | K4: 2
A5: 50 | B5: =IF(A5<30,"20-29",IF(A5<40,"30-39",IF(A5<50,"40-49",IF(A5<60,"50-59",IF(A5<70,"60-69",IF(A5<80,"70+")))))) -> 50-59 | C5: 2 | D5: 129 | E5: 196 | F5: 0 | G5: 1 | H5: 163 | I5: 0 | J5: 2 | K5: 2
A6: 51 | B6: =IF(A6<30,"20-29",IF(A6<40,"30-39",IF(A6<50,"40-49",IF(A6<60,"50-59",IF(A6<70,"60-69",IF(A6<80,"70+")))))) -> 50-59 | C6: 3 | D6: 125 | E6: 213 | F6: 0 | G6: 0 | H6: 125 | I6: 1 | J6: 2 | K6: 2
A7: 59 | B7: =IF(A7<30,"20-29",IF(A7<40,"30-39",IF(A7<50,"40-49",IF(A7<60,"50-59",IF(A7<70,"60-69",IF(A7<80,"70+")))))) -> 50-59 | C7: 0 | D7: 138 | E7: 271 | F7: 0 | G7: 0 | H7: 182 | I7: 0 | J7: 2 | K7: 2
A8: 64 | B8: =IF(A8<30,"20-29",IF(A8<40,"30-39",IF(A8<50,"40-49",IF(A8<60,"50-59",IF(A8<70,"60-69",IF(A8<80,"70+")))))) -> 60-69 | C8: 0 | D8: 128 | E8: 263 | F8: 0 | G8: 1 | H8: 105 | I8: 1 | J8: 1 | K8: 3
A9: 54 | B9: =IF(A9<30,"20-29",IF(A9<40,"30-39",IF(A9<50,"40-49",IF(A9<60,"50-59",IF(A9<70,"60-69",IF(A9<80,"70+")))))) -> 50-59 | C9: 2 | D9: 120 | E9: 258 | F9: 0 | G9: 0 | H9: 147 | I9: 0 | J9: 1 | K9: 3
A10: 42 | B10: =IF(A10<30,"20-29",IF(A10<40,"30-39",IF(A10<50,"40-49",IF(A10<60,"50-59",IF(A10<70,"60-69",IF(A10<80,"70+")))))) -> 40-49 | C10: 0 | D10: 140 | E10: 226 | F10: 0 | G10: 1 | H10: 178 | I10: 0 | J10: 2 | K10: 2
A11: 41 | B11: =IF(A11<30,"20-29",IF(A11<40,"30-39",IF(A11<50,"40-49",IF(A11<60,"50-59",IF(A11<70,"60-69",IF(A11<80,"70+")))))) -> 40-49 | C11: 1 | D11: 135 | E11: 203 | F11: 0 | G11: 1 | H11: 132 | I11: 0 | J11: 1 | K11: 1
A12: 38 | B12: =IF(A12<30,"20-29",IF(A12<40,"30-39",IF(A12<50,"40-49",IF(A12<60,"50-59",IF(A12<70,"60-69",IF(A12<80,"70+")))))) -> 30-39 | C12: 2 | D12: 138 | E12: 175 | F12: 0 | G12: 1 | H12: 173 | I12: 0 | J12: 2 | K12: 2
A13: 56 | B13: =IF(A13<30,"20-29",IF(A13<40,"30-39",IF(A13<50,"40-49",IF(A13<60,"50-59",IF(A13<70,"60-69",IF(A13<80,"70+")))))) -> 50-59 | C13: 3 | D13: 120 | E13: 193 | F13: 0 | G13: 0 | H13: 162 | I13: 0 | J13: 1 | K13: 3
... A20: 52 | B20: =IF(A20<30,"20-29",IF(A20<40,"30-39",IF(A20<50,"40-49",IF(A20<60,"50-59",IF(A20<70,"60-69",IF(A20<80,"70+")))))) -> 50-59 | C20: 1 | D20: 134 | E20: 201 | F20: 0 | G20: 1 | H20: 158 | I20: 0 | J20: 2 | K20: 2
A21: 44 | B21: =IF(A21<30,"20-29",IF(A21<40,"30-39",IF(A21<50,"40-49",IF(A21<60,"50-59",IF(A21<70,"60-69",IF(A21<80,"70+")))))) -> 40-49 | C21: 1 | D21: 120 | E21: 220 | F21: 0 | G21: 1 | H21: 170 | I21: 0 | J21: 2 | K21: 2 | M21: Variable | N21: Mean | O21: SD | P21: Min | Q21: Max
A22: 62 | B22: =IF(A22<30,"20-29",IF(A22<40,"30-39",IF(A22<50,"40-49",IF(A22<60,"50-59",IF(A22<70,"60-69",IF(A22<80,"70+")))))) -> 60-69 | C22: 1 | D22: 128 | E22: 208 | F22: 1 | G22: 0 | H22: 140 | I22: 0 | J22: 2 | K22: 2 | M22: Age | N22: =AVERAGE(A:A) -> 51.043478 | O22: =_xlfn.STDEV.P(A:A) -> 8.5769066 | P22: =MIN(A:A) -> 29 | Q22: =MAX(A:A) -> 70
A23: 62 | B23: =IF(A23<30,"20-29",IF(A23<40,"30-39",IF(A23<50,"40-49",IF(A23<60,"50-59",IF(A23<70,"60-69",IF(A23<80,"70+")))))) -> 60-69 | C23: 2 | D23: 130 | E23: 231 | F23: 0 | G23: 1 | H23: 146 | I23: 0 | J23: 1 | K23: 3 | M23: Resting BP | N23: =AVERAGE(D:D) -> 129.65217 | O23: =_xlfn.STDEV.P(D:D) -> 15.932217 | P23: =MIN(D:D) -> 94 | Q23: =MAX(D:D) -> 178
A24: 56 | B24: =IF(A24<30,"20-29",IF(A24<40,"30-39",IF(A24<50,"40-49",IF(A24<60,"50-59",IF(A24<70,"60-69",IF(A24<80,"70+")))))) -> 50-59 | C24: 1 | D24: 120 | E24: 236 | F24: 0 | G24: 1 | H24: 178 | I24: 0 | J24: 2 | K24: 2 | M24: Cholesterol | N24: =AVERAGE(E:E) -> 231.59783 | O24: =_xlfn.STDEV.P(E:E) -> 37.435759 | P24: =MIN(E:E) -> 126 | Q24: =MAX(E:E) -> 325
A25: 44 | B25: =IF(A25<30,"20-29",IF(A25<40,"30-39",IF(A25<50,"40-49",IF(A25<60,"50-59",IF(A25<70,"60-69",IF(A25<80,"70+")))))) -> 40-49 | C25: 1 | D25: 120 | E25: 263 | F25: 0 | G25: 1 | H25: 173 | I25: 0 | J25: 2 | K25: 3 | M25: Max HR | N25: =AVERAGE(H:H) -> 161.78261 | O25: =_xlfn.STDEV.P(H:H) -> 18.455485 | P25: =MIN(H:H) -> 105 | Q25: =MAX(H:H) -> 202
A26: 52 | B26: =IF(A26<30,"20-29",IF(A26<40,"30-39",IF(A26<50,"40-49",IF(A26<60,"50-59",IF(A26<70,"60-69",IF(A26<80,"70+")))))) -> 50-59 | C26: 0 | D26: 108 | E26: 233 | F26: 1 | G26: 1 | H26: 147 | I26: 0 | J26: 2 | K26: 3
A27: 42 | B27: =IF(A27<30,"20-29",IF(A27<40,"30-39",IF(A27<50,"40-49",IF(A27<60,"50-59",IF(A27<70,"60-69",IF(A27<80,"70+")))))) -> 40-49 | C27: 1 | D27: 120 | E27: 295 | F27: 0 | G27: 1 | H27: 162 | I27: 0 | J27: 2 | K27: 2
A28: 45 | B28: =IF(A28<30,"20-29",IF(A28<40,"30-39",IF(A28<50,"40-49",IF(A28<60,"50-59",IF(A28<70,"60-69",IF(A28<80,"70+")))))) -> 40-49 | C28: 1 | D28: 128 | E28: 308 | F28: 0 | G28: 0 | H28: 170 | I28: 0 | J28: 2 | K28: 2
A29: 57 | B29: =IF(A29<30,"20-29",IF(A29<40,"30-39",IF(A29<50,"40-49",IF(A29<60,"50-59",IF(A29<70,"60-69",IF(A29<80,"70+")))))) -> 50-59 | C29: 2 | D29: 150 | E29: 126 | F29: 1 | G29: 1 | H29: 173 | I29: 0 | J29: 2 | K29: 3
A30: 47 | B30: =IF(A30<30,"20-29",IF(A30<40,"30-39",IF(A30<50,"40-49",IF(A30<60,"50-59",IF(A30<70,"60-69",IF(A30<80,"70+")))))) -> 40-49 | C30: 0 | D30: 112 | E30: 204 | F30: 0 | G30: 1 | H30: 143 | I30: 0 | J30: 2 | K30: 2
A31: 59 | B31: =IF(A31<30,"20-29",IF(A31<40,"30-39",IF(A31<50,"40-49",IF(A31<60,"50-59",IF(A31<70,"60-69",IF(A31<80,"70+")))))) -> 50-59 | C31: 1 | D31: 140 | E31: 221 | F31: 0 | G31: 1 | H31: 164 | I31: 1 | J31: 2 | K31: 2
A32: 54 | B32: =IF(A32<30,"20-29",IF(A32<40,"30-39",IF(A32<50,"40-49",IF(A32<60,"50-59",IF(A32<70,"60-69",IF(A32<80,"70+")))))) -> 50-59 | C32: 1 | D32: 108 | E32: 309 | F32: 0 | G32: 1 | H32: 156 | I32: 0 | J32: 2 | K32: 3
A33: 52 | B33: =IF(A33<30,"20-29",IF(A33<40,"30-39",IF(A33<50,"40-49",IF(A33<60,"50-59",IF(A33<70,"60-69",IF(A33<80,"70+")))))) -> 50-59 | C33: 3 | D33: 118 | E33: 186 | F33: 0 | G33: 0 | H33: 190 | I33: 0 | J33: 1 | K33: 1
A34: 53 | B34: =IF(A34<30,"20-29",IF(A34<40,"30-39",IF(A34<50,"40-49",IF(A34<60,"50-59",IF(A34<70,"60-69",IF(A34<80,"70+")))))) -> 50-59 | C34: 0 | D34: 142 | E34: 226 | F34: 0 | G34: 0 | H34: 111 | I34: 1 | J34: 2 | K34: 3
A35: 66 | B35: =IF(A35<30,"20-29",IF(A35<40,"30-39",IF(A35<50,"40-49",IF(A35<60,"50-59",IF(A35<70,"60-69",IF(A35<80,"70+")))))) -> 60-69 | C35: 0 | D35: 120 | E35: 302 | F35: 0 | G35: 0 | H35: 151 | I35: 0 | J35: 1 | K35: 2
A36: 52 | B36: =IF(A36<30,"20-29",IF(A36<40,"30-39",IF(A36<50,"40-49",IF(A36<60,"50-59",IF(A36<70,"60-69",IF(A36<80,"70+")))))) -> 50-59 | C36: 2 | D36: 138 | E36: 223 | F36: 0 | G36: 1 | H36: 169 | I36: 0 | J36: 2 | K36: 2
A37: 57 | B37: =IF(A37<30,"20-29",IF(A37<40,"30-39",IF(A37<50,"40-49",IF(A37<60,"50-59",IF(A37<70,"60-69",IF(A37<80,"70+")))))) -> 50-59 | C37: 0 | D37: 140 | E37: 192 | F37: 0 | G37: 1 | H37: 148 | I37: 0 | J37: 1 | K37: 1
... A93: 65 | B93: =IF(A93<30,"20-29",IF(A93<40,"30-39",IF(A93<50,"40-49",IF(A93<60,"50-59",IF(A93<70,"60-69",IF(A93<80,"70+")))))) -> 60-69 | C93: 0 | D93: 120 | E93: 177 | F93: 0 | G93: 1 | H93: 140 | I93: 0 | J93: 2 | K93: 3

Sheet diseased-females
A1: age | B1: agegroup | C1: cpt | D1: restbps | E1: chol | F1: fbs | G1: restecg | H1: maxhr | I1: exang | J1: slope | K1: thal
A2: 58 | B2: =IF(A2<30,"20-29",IF(A2<40,"30-39",IF(A2<50,"40-49",IF(A2<60,"50-59",IF(A2<70,"60-69",IF(A2<80,"70+")))))) -> 50-59 | C2: 0 | D2: 100 | E2: 248 | F2: 0 | G2: 0 | H2: 122 | I2: 0 | J2: 1 | K2: 2
A3: 71 | B3: =IF(A3<30,"20-29",IF(A3<40,"30-39",IF(A3<50,"40-49",IF(A3<60,"50-59",IF(A3<70,"60-69",IF(A3<80,"70+")))))) -> 70+ | C3: 0 | D3: 112 | E3: 149 | F3: 0 | G3: 1 | H3: 125 | I3: 0 | J3: 1 | K3: 2
A4: 34 | B4: =IF(A4<30,"20-29",IF(A4<40,"30-39",IF(A4<50,"40-49",IF(A4<60,"50-59",IF(A4<70,"60-69",IF(A4<80,"70+")))))) -> 30-39 | C4: 1 | D4: 118 | E4: 210 | F4: 0 | G4: 1 | H4: 192 | I4: 0 | J4: 2 | K4: 2
A5: 51 | B5: =IF(A5<30,"20-29",IF(A5<40,"30-39",IF(A5<50,"40-49",IF(A5<60,"50-59",IF(A5<70,"60-69",IF(A5<80,"70+")))))) -> 50-59 | C5: 2 | D5: 140 | E5: 308 | F5: 0 | G5: 0 | H5: 142 | I5: 0 | J5: 2 | K5: 2
A6: 50 | B6: =IF(A6<30,"20-29",IF(A6<40,"30-39",IF(A6<50,"40-49",IF(A6<60,"50-59",IF(A6<70,"60-69",IF(A6<80,"70+")))))) -> 50-59 | C6: 1 | D6: 120 | E6: 244 | F6: 0 | G6: 1 | H6: 162 | I6: 0 | J6: 2 | K6: 2
A7: 67 | B7: =IF(A7<30,"20-29",IF(A7<40,"30-39",IF(A7<50,"40-49",IF(A7<60,"50-59",IF(A7<70,"60-69",IF(A7<80,"70+")))))) -> 60-69 | C7: 0 | D7: 106 | E7: 223 | F7: 0 | G7: 1 | H7: 142 | I7: 0 | J7: 2 | K7: 2
A8: 63 | B8: =IF(A8<30,"20-29",IF(A8<40,"30-39",IF(A8<50,"40-49",IF(A8<60,"50-59",IF(A8<70,"60-69",IF(A8<80,"70+")))))) -> 60-69 | C8: 2 | D8: 135 | E8: 252 | F8: 0 | G8: 0 | H8: 172 | I8: 0 | J8: 2 | K8: 2
A9: 42 | B9: =IF(A9<30,"20-29",IF(A9<40,"30-39",IF(A9<50,"40-49",IF(A9<60,"50-59",IF(A9<70,"60-69",IF(A9<80,"70+")))))) -> 40-49 | C9: 2 | D9: 120 | E9: 209 | F9: 0 | G9: 1 | H9: 173 | I9: 0 | J9: 1 | K9: 2
A10: 65 | B10: =IF(A10<30,"20-29",IF(A10<40,"30-39",IF(A10<50,"40-49",IF(A10<60,"50-59",IF(A10<70,"60-69",IF(A10<80,"70+")))))) -> 60-69 | C10: 2 | D10: 160 | E10: 360 | F10: 0 | G10: 0 | H10: 151 | I10: 0 | J10: 2 | K10: 2
A11: 55 | B11: =IF(A11<30,"20-29",IF(A11<40,"30-39",IF(A11<50,"40-49",IF(A11<60,"50-59",IF(A11<70,"60-69",IF(A11<80,"70+")))))) -> 50-59 | C11: 1 | D11: 132 | E11: 342 | F11: 0 | G11: 1 | H11: 166 | I11: 0 | J11: 2 | K11: 2
A12: 66 | B12: =IF(A12<30,"20-29",IF(A12<40,"30-39",IF(A12<50,"40-49",IF(A12<60,"50-59",IF(A12<70,"60-69",IF(A12<80,"70+")))))) -> 60-69 | C12: 2 | D12: 146 | E12: 278 | F12: 0 | G12: 0 | H12: 152 | I12: 0 | J12: 1 | K12: 2
A13: 58 | B13: =IF(A13<30,"20-29",IF(A13<40,"30-39",IF(A13<50,"40-49",IF(A13<60,"50-59",IF(A13<70,"60-69",IF(A13<80,"70+")))))) -> 50-59 | C13: 3 | D13: 150 | E13: 283 | F13: 1 | G13: 0 | H13: 162 | I13: 0 | J13: 2 | K13: 2
... A20: 43 | B20: =IF(A20<30,"20-29",IF(A20<40,"30-39",IF(A20<50,"40-49",IF(A20<60,"50-59",IF(A20<70,"60-69",IF(A20<80,"70+")))))) -> 40-49 | C20: 2 | D20: 122 | E20: 213 | F20: 0 | G20: 1 | H20: 165 | I20: 0 | J20: 1 | K20: 2
A21: 67 | B21: =IF(A21<30,"20-29",IF(A21<40,"30-39",IF(A21<50,"40-49",IF(A21<60,"50-59",IF(A21<70,"60-69",IF(A21<80,"70+")))))) -> 60-69 | C21: 2 | D21: 115 | E21: 564 | F21: 0 | G21: 0 | H21: 160 | I21: 0 | J21: 1 | K21: 3 | M21: Variable | N21: Mean | O21: SD | P21: Min | Q21: Max
A22: 71 | B22: =IF(A22<30,"20-29",IF(A22<40,"30-39",IF(A22<50,"40-49",IF(A22<60,"50-59",IF(A22<70,"60-69",IF(A22<80,"70+")))))) -> 70+ | C22: 1 | D22: 160 | E22: 302 | F22: 0 | G22: 1 | H22: 162 | I22: 0 | J22: 2 | K22: 2 | M22: Age | N22: =AVERAGE(A:A) -> 54.555556 | O22: =_xlfn.STDEV.P(A:A) -> 10.193801 | P22: =MIN(A:A) -> 34 | Q22: =MAX(A:A) -> 76
A23: 50 | B23: =IF(A23<30,"20-29",IF(A23<40,"30-39",IF(A23<50,"40-49",IF(A23<60,"50-59",IF(A23<70,"60-69",IF(A23<80,"70+")))))) -> 50-59 | C23: 0 | D23: 110 | E23: 254 | F23: 0 | G23: 0 | H23: 159 | I23: 0 | J23: 2 | K23: 2 | M23: Resting BP | N23: =AVERAGE(D:D) -> 128.73611 | O23: =_xlfn.STDEV.P(D:D) -> 16.421525 | P23: =MIN(D:D) -> 94 | Q23: =MAX(D:D) -> 180
A24: 44 | B24: =IF(A24<30,"20-29",IF(A24<40,"30-39",IF(A24<50,"40-49",IF(A24<60,"50-59",IF(A24<70,"60-69",IF(A24<80,"70+")))))) -> 40-49 | C24: 2 | D24: 108 | E24: 141 | F24: 0 | G24: 1 | H24: 175 | I24: 0 | J24: 1 | K24: 2 | M24: Cholesterol | N24: =AVERAGE(E:E) -> 256.75 | O24: =_xlfn.STDEV.P(E:E) -> 65.754753 | P24: =MIN(E:E) -> 141 | Q24: =MAX(E:E) -> 564
A25: 65 | B25: =IF(A25<30,"20-29",IF(A25<40,"30-39",IF(A25<50,"40-49",IF(A25<60,"50-59",IF(A25<70,"60-69",IF(A25<80,"70+")))))) -> 60-69 | C25: 2 | D25: 140 | E25: 417 | F25: 1 | G25: 0 | H25: 157 | I25: 0 | J25: 2 | K25: 2 | M25: Max HR | N25: =AVERAGE(H:H) -> 154.02778 | O25: =_xlfn.STDEV.P(H:H) -> 19.118761 | P25: =MIN(H:H) -> 96 | Q25: =MAX(H:H) -> 192
A26: 60 | B26: =IF(A26<30,"20-29",IF(A26<40,"30-39",IF(A26<50,"40-49",IF(A26<60,"50-59",IF(A26<70,"60-69",IF(A26<80,"70+")))))) -> 60-69 | C26: 3 | D26: 150 | E26: 240 | F26: 0 | G26: 1 | H26: 171 | I26: 0 | J26: 2 | K26: 2
A27: 51 | B27: =IF(A27<30,"20-29",IF(A27<40,"30-39",IF(A27<50,"40-49",IF(A27<60,"50-59",IF(A27<70,"60-69",IF(A27<80,"70+")))))) -> 50-59 | C27: 2 | D27: 130 | E27: 256 | F27: 0 | G27: 0 | H27: 149 | I27: 0 | J27: 2 | K27: 2
A28: 64 | B28: =IF(A28<30,"20-29",IF(A28<40,"30-39",IF(A28<50,"40-49",IF(A28<60,"50-59",IF(A28<70,"60-69",IF(A28<80,"70+")))))) -> 60-69 | C28: 0 | D28: 180 | E28: 325 | F28: 0 | G28: 1 | H28: 154 | I28: 1 | J28: 2 | K28: 2
A29: 51 | B29: =IF(A29<30,"20-29",IF(A29<40,"30-39",IF(A29<50,"40-49",IF(A29<60,"50-59",IF(A29<70,"60-69",IF(A29<80,"70+")))))) -> 50-59 | C29: 2 | D29: 120 | E29: 295 | F29: 0 | G29: 0 | H29: 157 | I29: 0 | J29: 2 | K29: 2
A30: 57 | B30: =IF(A30<30,"20-29",IF(A30<40,"30-39",IF(A30<50,"40-49",IF(A30<60,"50-59",IF(A30<70,"60-69",IF(A30<80,"70+")))))) -> 50-59 | C30: 0 | D30: 120 | E30: 354 | F30: 0 | G30: 1 | H30: 163 | I30: 1 | J30: 2 | K30: 2
A31: 45 | B31: =IF(A31<30,"20-29",IF(A31<40,"30-39",IF(A31<50,"40-49",IF(A31<60,"50-59",IF(A31<70,"60-69",IF(A31<80,"70+")))))) -> 40-49 | C31: 1 | D31: 112 | E31: 160 | F31: 0 | G31: 1 | H31: 138 | I31: 0 | J31: 1 | K31: 2
A32: 39 | B32: =IF(A32<30,"20-29",IF(A32<40,"30-39",IF(A32<50,"40-49",IF(A32<60,"50-59",IF(A32<70,"60-69",IF(A32<80,"70+")))))) -> 30-39 | C32: 2 | D32: 94 | E32: 199 | F32: 0 | G32: 1 | H32: 179 | I32: 0 | J32: 2 | K32: 2
A33: 60 | B33: =IF(A33<30,"20-29",IF(A33<40,"30-39",IF(A33<50,"40-49",IF(A33<60,"50-59",IF(A33<70,"60-69",IF(A33<80,"70+")))))) -> 60-69 | C33: 2 | D33: 102 | E33: 318 | F33: 0 | G33: 1 | H33: 160 | I33: 0 | J33: 2 | K33: 2
A34: 44 | B34: =IF(A34<30,"20-29",IF(A34<40,"30-39",IF(A34<50,"40-49",IF(A34<60,"50-59",IF(A34<70,"60-69",IF(A34<80,"70+")))))) -> 40-49 | C34: 2 | D34: 118 | E34: 242 | F34: 0 | G34: 1 | H34: 149 | I34: 0 | J34: 1 | K34: 2
A35: 41 | B35: =IF(A35<30,"20-29",IF(A35<40,"30-39",IF(A35<50,"40-49",IF(A35<60,"50-59",IF(A35<70,"60-69",IF(A35<80,"70+")))))) -> 40-49 | C35: 1 | D35: 126 | E35: 306 | F35: 0 | G35: 1 | H35: 163 | I35: 0 | J35: 2 | K35: 2
A36: 49 | B36: =IF(A36<30,"20-29",IF(A36<40,"30-39",IF(A36<50,"40-49",IF(A36<60,"50-59",IF(A36<70,"60-69",IF(A36<80,"70+")))))) -> 40-49 | C36: 0 | D36: 130 | E36: 269 | F36: 0 | G36: 1 | H36: 163 | I36: 0 | J36: 2 | K36: 2
A37: 54 | B37: =IF(A37<30,"20-29",IF(A37<40,"30-39",IF(A37<50,"40-49",IF(A37<60,"50-59",IF(A37<70,"60-69",IF(A37<80,"70+")))))) -> 50-59 | C37: 1 | D37: 132 | E37: 288 | F37: 1 | G37: 0 | H37: 159 | I37: 1 | J37: 2 | K37: 2
... A73: 68 | B73: =IF(A73<30,"20-29",IF(A73<40,"30-39",IF(A73<50,"40-49",IF(A73<60,"50-59",IF(A73<70,"60-69",IF(A73<80,"70+")))))) -> 60-69 | C73: 2 | D73: 120 | E73: 211 | F73: 0 | G73: 0 | H73: 115 | I73: 0 | J73: 1 | K73: 2

Sheet non-diseased_males
A1: age | B1: agegroup | C1: cpt | D1: restbps | E1: chol | F1: fbs | G1: restecg | H1: maxhr | I1: exang | J1: slope | K1: thal
A2: 55 | B2: =IF(A2<30,"20-29",IF(A2<40,"30-39",IF(A2<50,"40-49",IF(A2<60,"50-59",IF(A2<70,"60-69",IF(A2<80,"70+")))))) -> 50-59 | C2: 0 | D2: 132 | E2: 353 | F2: 0 | G2: 1 | H2: 132 | I2: 1 | J2: 1 | K2: 3 | M2: Variable | N2: Mean | O2: SD | P2: Min | Q2: Max
A3: 57 | B3: =IF(A3<30,"20-29",IF(A3<40,"30-39",IF(A3<50,"40-49",IF(A3<60,"50-59",IF(A3<70,"60-69",IF(A3<80,"70+")))))) -> 50-59 | C3: 0 | D3: 110 | E3: 335 | F3: 0 | G3: 1 | H3: 143 | I3: 1 | J3: 1 | K3: 3 | M3: Age | N3: =AVERAGE(A:A) -> 56.087719 | O3: =_xlfn.STDEV.P(A:A) -> 8.3482968 | P3: =MIN(A:A) -> 35 | Q3: =MAX(A:A) -> 77
A4: 64 | B4: =IF(A4<30,"20-29",IF(A4<40,"30-39",IF(A4<50,"40-49",IF(A4<60,"50-59",IF(A4<70,"60-69",IF(A4<80,"70+")))))) -> 60-69 | C4: 2 | D4: 140 | E4: 335 | F4: 0 | G4: 1 | H4: 158 | I4: 0 | J4: 2 | K4: 2 | M4: Resting BP | N4: =AVERAGE(D:D) -> 131.92982 | O4: =_xlfn.STDEV.P(D:D) -> 17.14168 | P4: =MIN(D:D) -> 100 | Q4: =MAX(D:D) -> 192
A5: 63 | B5: =IF(A5<30,"20-29",IF(A5<40,"30-39",IF(A5<50,"40-49",IF(A5<60,"50-59",IF(A5<70,"60-69",IF(A5<80,"70+")))))) -> 60-69 | C5: 0 | D5: 130 | E5: 330 | F5: 1 | G5: 0 | H5: 132 | I5: 1 | J5: 2 | K5: 3 | M5: Cholesterol | N5: =AVERAGE(E:E) -> 246.0614 | O5: =_xlfn.STDEV.P(E:E) -> 45.23938 | P5: =MIN(E:E) -> 131 | Q5: =MAX(E:E) -> 353
A6: 59 | B6: =IF(A6<30,"20-29",IF(A6<40,"30-39",IF(A6<50,"40-49",IF(A6<60,"50-59",IF(A6<70,"60-69",IF(A6<80,"70+")))))) -> 50-59 | C6: 0 | D6: 170 | E6: 326 | F6: 0 | G6: 0 | H6: 140 | I6: 1 | J6: 0 | K6: 3 | M6: Max HR | N6: =AVERAGE(H:H) -> 138.40351 | O6: =_xlfn.STDEV.P(H:H) -> 22.981579 | P6: =MIN(H:H) -> 71 | Q6: =MAX(H:H) -> 195
A7: 70 | B7: =IF(A7<30,"20-29",IF(A7<40,"30-39",IF(A7<50,"40-49",IF(A7<60,"50-59",IF(A7<70,"60-69",IF(A7<80,"70+")))))) -> 70+ | C7: 0 | D7: 130 | E7: 322 | F7: 0 | G7: 0 | H7: 109 | I7: 0 | J7: 1 | K7: 2
A8: 58 | B8: =IF(A8<30,"20-29",IF(A8<40,"30-39",IF(A8<50,"40-49",IF(A8<60,"50-59",IF(A8<70,"60-69",IF(A8<80,"70+")))))) -> 50-59 | C8: 0 | D8: 114 | E8: 318 | F8: 0 | G8: 2 | H8: 140 | I8: 0 | J8: 0 | K8: 1
A9: 42 | B9: =IF(A9<30,"20-29",IF(A9<40,"30-39",IF(A9<50,"40-49",IF(A9<60,"50-59",IF(A9<70,"60-69",IF(A9<80,"70+")))))) -> 40-49 | C9: 0 | D9: 136 | E9: 315 | F9: 0 | G9: 1 | H9: 125 | I9: 1 | J9: 1 | K9: 1
A10: 46 | B10: =IF(A10<30,"20-29",IF(A10<40,"30-39",IF(A10<50,"40-49",IF(A10<60,"50-59",IF(A10<70,"60-69",IF(A10<80,"70+")))))) -> 40-49 | C10: 0 | D10: 140 | E10: 311 | F10: 0 | G10: 1 | H10: 120 | I10: 1 | J10: 1 | K10: 3
A11: 64 | B11: =IF(A11<30,"20-29",IF(A11<40,"30-39",IF(A11<50,"40-49",IF(A11<60,"50-59",IF(A11<70,"60-69",IF(A11<80,"70+")))))) -> 60-69 | C11: 2 | D11: 125 | E11: 309 | F11: 0 | G11: 1 | H11: 131 | I11: 1 | J11: 1 | K11: 3
A12: 45 | B12: =IF(A12<30,"20-29",IF(A12<40,"30-39",IF(A12<50,"40-49",IF(A12<60,"50-59",IF(A12<70,"60-69",IF(A12<80,"70+")))))) -> 40-49 | C12: 0 | D12: 142 | E12: 309 | F12: 0 | G12: 0 | H12: 147 | I12: 1 | J12: 1 | K12: 3
A13: 77 | B13: =IF(A13<30,"20-29",IF(A13<40,"30-39",IF(A13<50,"40-49",IF(A13<60,"50-59",IF(A13<70,"60-69",IF(A13<80,"70+")))))) -> 70+ | C13: 0 | D13: 125 | E13: 304 | F13: 0 | G13: 0 | H13: 162 | I13: 1 | J13: 2 | K13: 2
A14: 58 | B14: =IF(A14<30,"20-29",IF(A14<40,"30-39",IF(A14<50,"40-49",IF(A14<60,"50-59",IF(A14<70,"60-69",IF(A14<80,"70+")))))) -> 50-59 | C14: 0 | D14: 125 | E14: 300 | F14: 0 | G14: 0 | H14: 171 | I14: 0 | J14: 2 | K14: 3
A15: 67 | B15: =IF(A15<30,"20-29",IF(A15<40,"30-39",IF(A15<50,"40-49",IF(A15<60,"50-59",IF(A15<70,"60-69",IF(A15<80,"70+")))))) -> 60-69 | C15: 0 | D15: 100 | E15: 299 | F15: 0 | G15: 0 | H15: 125 | I15: 1 | J15: 1 | K15: 2
A16: 51 | B16: =IF(A16<30,"20-29",IF(A16<40,"30-39",IF(A16<50,"40-49",IF(A16<60,"50-59",IF(A16<70,"60-69",IF(A16<80,"70+")))))) -> 50-59 | C16: 0 | D16: 140 | E16: 299 | F16: 0 | G16: 1 | H16: 173 | I16: 1 | J16: 2 | K16: 3
A17: 51 | B17: =IF(A17<30,"20-29",IF(A17<40,"30-39",IF(A17<50,"40-49",IF(A17<60,"50-59",IF(A17<70,"60-69",IF(A17<80,"70+")))))) -> 50-59 | C17: 0 | D17: 140 | E17: 298 | F17: 0 | G17: 1 | H17: 122 | I17: 1 | J17: 1 | K17: 3
A18: 60 | B18: =IF(A18<30,"20-29",IF(A18<40,"30-39",IF(A18<50,"40-49",IF(A18<60,"50-59",IF(A18<70,"60-69",IF(A18<80,"70+")))))) -> 60-69 | C18: 0 | D18: 140 | E18: 293 | F18: 0 | G18: 0 | H18: 170 | I18: 0 | J18: 1 | K18: 3
... A115: 57 | B115: =IF(A115<30,"20-29",IF(A115<40,"30-39",IF(A115<50,"40-49",IF(A115<60,"50-59",IF(A115<70,"60-69",IF(A115<80,"70+")))))) -> 50-59 | C115: 0 | D115: 130 | E115: 131 | F115: 0 | G115: 1 | H115: 115 | I115: 1 | J115: 1 | K115: 3

Sheet non-diseased_females
A1: age | B1: agegroup | C1: cpt | D1: restbps | E1: chol | F1: fbs | G1: restecg | H1: maxhr | I1: exang | J1: slope | K1: thal
A2: 56 | B2: =IF(A2<30,"20-29",IF(A2<40,"30-39",IF(A2<50,"40-49",IF(A2<60,"50-59",IF(A2<70,"60-69",IF(A2<80,"70+")))))) -> 50-59 | C2: 0 | D2: 134 | E2: 409 | F2: 0 | G2: 0 | H2: 150 | I2: 1 | J2: 1 | K2: 3 | M2: Variable | N2: Mean | O2: SD | P2: Min | Q2: Max
A3: 63 | B3: =IF(A3<30,"20-29",IF(A3<40,"30-39",IF(A3<50,"40-49",IF(A3<60,"50-59",IF(A3<70,"60-69",IF(A3<80,"70+")))))) -> 60-69 | C3: 0 | D3: 150 | E3: 407 | F3: 0 | G3: 0 | H3: 154 | I3: 0 | J3: 1 | K3: 3 | M3: Age | N3: =AVERAGE(A:A) -> 59.041667 | O3: =_xlfn.STDEV.P(A:A) -> 4.8603769 | P3: =MIN(A:A) -> 43 | Q3: =MAX(A:A) -> 66
A4: 43 | B4: =IF(A4<30,"20-29",IF(A4<40,"30-39",IF(A4<50,"40-49",IF(A4<60,"50-59",IF(A4<70,"60-69",IF(A4<80,"70+")))))) -> 40-49 | C4: 0 | D4: 132 | E4: 341 | F4: 1 | G4: 0 | H4: 136 | I4: 1 | J4: 1 | K4: 3 | M4: Resting BP | N4: =AVERAGE(D:D) -> 146.125 | O4: =_xlfn.STDEV.P(D:D) -> 20.984741 | P4: =MIN(D:D) -> 108 | Q4: =MAX(D:D) -> 200
A5: 61 | B5: =IF(A5<30,"20-29",IF(A5<40,"30-39",IF(A5<50,"40-49",IF(A5<60,"50-59",IF(A5<70,"60-69",IF(A5<80,"70+")))))) -> 60-69 | C5: 0 | D5: 130 | E5: 330 | F5: 0 | G5: 0 | H5: 169 | I5: 0 | J5: 2 | K5: 2 | M5: Cholesterol | N5: =AVERAGE(E:E) -> 274.95833 | O5: =_xlfn.STDEV.P(E:E) -> 59.582212 | P5: =MIN(E:E) -> 164 | Q5: =MAX(E:E) -> 409
A6: 55 | B6: =IF(A6<30,"20-29",IF(A6<40,"30-39",IF(A6<50,"40-49",IF(A6<60,"50-59",IF(A6<70,"60-69",IF(A6<80,"70+")))))) -> 50-59 | C6: 0 | D6: 180 | E6: 327 | F6: 0 | G6: 2 | H6: 117 | I6: 1 | J6: 1 | K6: 2 | M6: Max HR | N6: =AVERAGE(H:H) -> 142.41667 | O6: =_xlfn.STDEV.P(H:H) -> 19.830357 | P6: =MIN(H:H) -> 97 | Q6: =MAX(H:H) -> 174
A7: 58 | B7: =IF(A7<30,"20-29",IF(A7<40,"30-39",IF(A7<50,"40-49",IF(A7<60,"50-59",IF(A7<70,"60-69",IF(A7<80,"70+")))))) -> 50-59 | C7: 1 | D7: 136 | E7: 319 | F7: 1 | G7: 0 | H7: 152 | I7: 0 | J7: 2 | K7: 2
A8: 61 | B8: =IF(A8<30,"20-29",IF(A8<40,"30-39",IF(A8<50,"40-49",IF(A8<60,"50-59",IF(A8<70,"60-69",IF(A8<80,"70+")))))) -> 60-69 | C8: 0 | D8: 145 | E8: 307 | F8: 0 | G8: 0 | H8: 146 | I8: 1 | J8: 1 | K8: 3
A9: 51 | B9: =IF(A9<30,"20-29",IF(A9<40,"30-39",IF(A9<50,"40-49",IF(A9<60,"50-59",IF(A9<70,"60-69",IF(A9<80,"70+")))))) -> 50-59 | C9: 0 | D9: 130 | E9: 305 | F9: 0 | G9: 1 | H9: 142 | I9: 1 | J9: 1 | K9: 3
A10: 62 | B10: =IF(A10<30,"20-29",IF(A10<40,"30-39",IF(A10<50,"40-49",IF(A10<60,"50-59",IF(A10<70,"60-69",IF(A10<80,"70+")))))) -> 60-69 | C10: 0 | D10: 138 | E10: 294 | F10: 1 | G10: 1 | H10: 106 | I10: 0 | J10: 1 | K10: 2
A11: 56 | B11: =IF(A11<30,"20-29",IF(A11<40,"30-39",IF(A11<50,"40-49",IF(A11<60,"50-59",IF(A11<70,"60-69",IF(A11<80,"70+")))))) -> 50-59 | C11: 0 | D11: 200 | E11: 288 | F11: 1 | G11: 0 | H11: 133 | I11: 1 | J11: 0 | K11: 3
A12: 63 | B12: =IF(A12<30,"20-29",IF(A12<40,"30-39",IF(A12<50,"40-49",IF(A12<60,"50-59",IF(A12<70,"60-69",IF(A12<80,"70+")))))) -> 60-69 | C12: 0 | D12: 108 | E12: 269 | F12: 0 | G12: 1 | H12: 169 | I12: 1 | J12: 1 | K12: 2
A13: 62 | B13: =IF(A13<30,"20-29",IF(A13<40,"30-39",IF(A13<50,"40-49",IF(A13<60,"50-59",IF(A13<70,"60-69",IF(A13<80,"70+")))))) -> 60-69 | C13: 0 | D13: 140 | E13: 268 | F13: 0 | G13: 0 | H13: 160 | I13: 0 | J13: 0 | K13: 2
A14: 62 | B14: =IF(A14<30,"20-29",IF(A14<40,"30-39",IF(A14<50,"40-49",IF(A14<60,"50-59",IF(A14<70,"60-69",IF(A14<80,"70+")))))) -> 60-69 | C14: 2 | D14: 130 | E14: 263 | F14: 0 | G14: 1 | H14: 97 | I14: 0 | J14: 1 | K14: 3
A15: 60 | B15: =IF(A15<30,"20-29",IF(A15<40,"30-39",IF(A15<50,"40-49",IF(A15<60,"50-59",IF(A15<70,"60-69",IF(A15<80,"70+")))))) -> 60-69 | C15: 0 | D15: 150 | E15: 258 | F15: 0 | G15: 0 | H15: 157 | I15: 0 | J15: 1 | K15: 3
A16: 59 | B16: =IF(A16<30,"20-29",IF(A16<40,"30-39",IF(A16<50,"40-49",IF(A16<60,"50-59",IF(A16<70,"60-69",IF(A16<80,"70+")))))) -> 50-59 | C16: 0 | D16: 174 | E16: 249 | F16: 0 | G16: 1 | H16: 143 | I16: 1 | J16: 1 | K16: 2
A17: 62 | B17: =IF(A17<30,"20-29",IF(A17<40,"30-39",IF(A17<50,"40-49",IF(A17<60,"50-59",IF(A17<70,"60-69",IF(A17<80,"70+")))))) -> 60-69 | C17: 0 | D17: 150 | E17: 244 | F17: 0 | G17: 1 | H17: 154 | I17: 1 | J17: 1 | K17: 2
A18: 57 | B18: =IF(A18<30,"20-29",IF(A18<40,"30-39",IF(A18<50,"40-49",IF(A18<60,"50-59",IF(A18<70,"60-69",IF(A18<80,"70+")))))) -> 50-59 | C18: 0 | D18: 140 | E18: 241 | F18: 0 | G18: 1 | H18: 123 | I18: 1 | J18: 1 | K18: 3
... A25: 62 | B25: =IF(A25<30,"20-29",IF(A25<40,"30-39",IF(A25<50,"40-49",IF(A25<60,"50-59",IF(A25<70,"60-69",IF(A25<80,"70+")))))) -> 60-69 | C25: 0 | D25: 160 | E25: 164 | F25: 0 | G25: 0 | H25: 145 | I25: 0 | J25: 0 | K25: 3
