Workbook

Sheet cleveland_data
A1: age | B1: sex | C1: cpt | D1: rbp | E1: chol | F1: fbs | G1: restecg | H1: maxhr | I1: exang | J1: slope | K1: thal | L1: num | M1: hd
A2: 63 | B2: 1 | C2: 1 | D2: 145 | E2: 233 | F2: 1 | G2: 2 | H2: 150 | I2: 0 | J2: 3 | K2: 6 | L2: 0 | M2: =IF(ClevelandData[[#This Row],[num]]=0,0,1) -> 0
A3: 67 | B3: 1 | C3: 4 | D3: 160 | E3: 286 | F3: 0 | G3: 2 | H3: 108 | I3: 1 | J3: 2 | K3: 3 | L3: 2 | M3: =IF(ClevelandData[[#This Row],[num]]=0,0,1) -> 1
A4: 67 | B4: 1 | C4: 4 | D4: 120 | E4: 229 | F4: 0 | G4: 2 | H4: 129 | I4: 1 | J4: 2 | K4: 7 | L4: 1 | M4: =IF(ClevelandData[[#This Row],[num]]=0,0,1) -> 1
A5: 37 | B5: 1 | C5: 3 | D5: 130 | E5: 250 | F5: 0 | G5: 0 | H5: 187 | I5: 0 | J5: 3 | K5: 3 | L5: 0 | M5: =IF(ClevelandData[[#This Row],[num]]=0,0,1) -> 0
A6: 41 | B6: 0 | C6: 2 | D6: 130 | E6: 204 | F6: 0 | G6: 2 | H6: 172 | I6: 0 | J6: 1 | K6: 3 | L6: 0 | M6: =IF(ClevelandData[[#This Row],[num]]=0,0,1) -> 0
A7: 56 | B7: 1 | C7: 2 | D7: 120 | E7: 236 | F7: 0 | G7: 0 | H7: 178 | I7: 0 | J7: 1 | K7: 3 | L7: 0 | M7: =IF(ClevelandData[[#This Row],[num]]=0,0,1) -> 0
A8: 62 | B8: 0 | C8: 4 | D8: 140 | E8: 268 | F8: 0 | G8: 2 | H8: 160 | I8: 0 | J8: 3 | K8: 3 | L8: 3 | M8: =IF(ClevelandData[[#This Row],[num]]=0,0,1) -> 1
A9: 57 | B9: 0 | C9: 4 | D9: 120 | E9: 354 | F9: 0 | G9: 0 | H9: 163 | I9: 1 | J9: 1 | K9: 3 | L9: 0 | M9: =IF(ClevelandData[[#This Row],[num]]=0,0,1) -> 0
A10: 63 | B10: 1 | C10: 4 | D10: 130 | E10: 254 | F10: 0 | G10: 2 | H10: 147 | I10: 0 | J10: 2 | K10: 7 | L10: 2 | M10: =IF(ClevelandData[[#This Row],[num]]=0,0,1) -> 1
A11: 53 | B11: 1 | C11: 4 | D11: 140 | E11: 203 | F11: 1 | G11: 2 | H11: 155 | I11: 1 | J11: 3 | K11: 7 | L11: 1 | M11: =IF(ClevelandData[[#This Row],[num]]=0,0,1) -> 1
A12: 57 | B12: 1 | C12: 4 | D12: 140 | E12: 192 | F12: 0 | G12: 0 | H12: 148 | I12: 0 | J12: 2 | K12: 6 | L12: 0 | M12: =IF(ClevelandData[[#This Row],[num]]=0,0,1) -> 0
A13: 56 | B13: 0 | C13: 2 | D13: 140 | E13: 294 | F13: 0 | G13: 2 | H13: 153 | I13: 0 | J13: 2 | K13: 3 | L13: 0 | M13: =IF(ClevelandData[[#This Row],[num]]=0,0,1) -> 0
... A88: 47 | B88: 1 | C88: 3 | D88: 138 | E88: 257 | F88: 0 | G88: 2 | H88: 156 | I88: 0 | J88: 1 | K88: 3 | L88: 0 | M88: =IF(ClevelandData[[#This Row],[num]]=0,0,1) -> 0
A89: 53 | B89: 0 | C89: 3 | D89: 128 | E89: 216 | F89: 0 | G89: 2 | H89: 115 | I89: 0 | J89: 1 | K89: ? | L89: 0 | M89: =IF(ClevelandData[[#This Row],[num]]=0,0,1) -> 0
A90: 53 | B90: 0 | C90: 4 | D90: 138 | E90: 234 | F90: 0 | G90: 2 | H90: 160 | I90: 0 | J90: 1 | K90: 3 | L90: 0 | M90: =IF(ClevelandData[[#This Row],[num]]=0,0,1) -> 0
A91: 51 | B91: 0 | C91: 3 | D91: 130 | E91: 256 | F91: 0 | G91: 2 | H91: 149 | I91: 0 | J91: 1 | K91: 3 | L91: 0 | M91: =IF(ClevelandData[[#This Row],[num]]=0,0,1) -> 0
A92: 66 | B92: 1 | C92: 4 | D92: 120 | E92: 302 | F92: 0 | G92: 2 | H92: 151 | I92: 0 | J92: 2 | K92: 3 | L92: 0 | M92: =IF(ClevelandData[[#This Row],[num]]=0,0,1) -> 0
A93: 62 | B93: 0 | C93: 4 | D93: 160 | E93: 164 | F93: 0 | G93: 2 | H93: 145 | I93: 0 | J93: 3 | K93: 7 | L93: 3 | M93: =IF(ClevelandData[[#This Row],[num]]=0,0,1) -> 1
A94: 62 | B94: 1 | C94: 3 | D94: 130 | E94: 231 | F94: 0 | G94: 0 | H94: 146 | I94: 0 | J94: 2 | K94: 7 | L94: 0 | M94: =IF(ClevelandData[[#This Row],[num]]=0,0,1) -> 0
A95: 44 | B95: 0 | C95: 3 | D95: 108 | E95: 141 | F95: 0 | G95: 0 | H95: 175 | I95: 0 | J95: 2 | K95: 3 | L95: 0 | M95: =IF(ClevelandData[[#This Row],[num]]=0,0,1) -> 0
A96: 63 | B96: 0 | C96: 3 | D96: 135 | E96: 252 | F96: 0 | G96: 2 | H96: 172 | I96: 0 | J96: 1 | K96: 3 | L96: 0 | M96: =IF(ClevelandData[[#This Row],[num]]=0,0,1) -> 0
A97: 52 | B97: 1 | C97: 4 | D97: 128 | E97: 255 | F97: 0 | G97: 0 | H97: 161 | I97: 1 | J97: 1 | K97: 7 | L97: 1 | M97: =IF(ClevelandData[[#This Row],[num]]=0,0,1) -> 1
A98: 59 | B98: 1 | C98: 4 | D98: 110 | E98: 239 | F98: 0 | G98: 2 | H98: 142 | I98: 1 | J98: 2 | K98: 7 | L98: 2 | M98: =IF(ClevelandData[[#This Row],[num]]=0,0,1) -> 1
A99: 60 | B99: 0 | C99: 4 | D99: 150 | E99: 258 | F99: 0 | G99: 2 | H99: 157 | I99: 0 | J99: 2 | K99: 7 | L99: 3 | M99: =IF(ClevelandData[[#This Row],[num]]=0,0,1) -> 1
A100: 52 | B100: 1 | C100: 2 | D100: 134 | E100: 201 | F100: 0 | G100: 0 | H100: 158 | I100: 0 | J100: 1 | K100: 3 | L100: 0 | M100: =IF(ClevelandData[[#This Row],[num]]=0,0,1) -> 0
A101: 48 | B101: 1 | C101: 4 | D101: 122 | E101: 222 | F101: 0 | G101: 2 | H101: 186 | I101: 0 | J101: 1 | K101: 3 | L101: 0 | M101: =IF(ClevelandData[[#This Row],[num]]=0,0,1) -> 0
... A267: 42 | B267: 1 | C267: 4 | D267: 136 | E267: 315 | F267: 0 | G267: 0 | H267: 125 | I267: 1 | J267: 2 | K267: 6 | L267: 2 | M267: =IF(ClevelandData[[#This Row],[num]]=0,0,1) -> 1
A268: 52 | B268: 1 | C268: 4 | D268: 128 | E268: 204 | F268: 1 | G268: 0 | H268: 156 | I268: 1 | J268: 2 | K268: ? | L268: 2 | M268: =IF(ClevelandData[[#This Row],[num]]=0,0,1) -> 1
A269: 59 | B269: 1 | C269: 3 | D269: 126 | E269: 218 | F269: 1 | G269: 0 | H269: 134 | I269: 0 | J269: 2 | K269: 6 | L269: 2 | M269: =IF(ClevelandData[[#This Row],[num]]=0,0,1) -> 1
A270: 40 | B270: 1 | C270: 4 | D270: 152 | E270: 223 | F270: 0 | G270: 0 | H270: 181 | I270: 0 | J270: 1 | K270: 7 | L270: 1 | M270: =IF(ClevelandData[[#This Row],[num]]=0,0,1) -> 1
A271: 42 | B271: 1 | C271: 3 | D271: 130 | E271: 180 | F271: 0 | G271: 0 | H271: 150 | I271: 0 | J271: 1 | K271: 3 | L271: 0 | M271: =IF(ClevelandData[[#This Row],[num]]=0,0,1) -> 0
A272: 61 | B272: 1 | C272: 4 | D272: 140 | E272: 207 | F272: 0 | G272: 2 | H272: 138 | I272: 1 | J272: 1 | K272: 7 | L272: 1 | M272: =IF(ClevelandData[[#This Row],[num]]=0,0,1) -> 1
A273: 66 | B273: 1 | C273: 4 | D273: 160 | E273: 228 | F273: 0 | G273: 2 | H273: 138 | I273: 0 | J273: 1 | K273: 6 | L273: 0 | M273: =IF(ClevelandData[[#This Row],[num]]=0,0,1) -> 0
A274: 46 | B274: 1 | C274: 4 | D274: 140 | E274: 311 | F274: 0 | G274: 0 | H274: 120 | I274: 1 | J274: 2 | K274: 7 | L274: 2 | M274: =IF(ClevelandData[[#This Row],[num]]=0,0,1) -> 1
A275: 71 | B275: 0 | C275: 4 | D275: 112 | E275: 149 | F275: 0 | G275: 0 | H275: 125 | I275: 0 | J275: 2 | K275: 3 | L275: 0 | M275: =IF(ClevelandData[[#This Row],[num]]=0,0,1) -> 0
A276: 59 | B276: 1 | C276: 1 | D276: 134 | E276: 204 | F276: 0 | G276: 0 | H276: 162 | I276: 0 | J276: 1 | K276: 3 | L276: 1 | M276: =IF(ClevelandData[[#This Row],[num]]=0,0,1) -> 1
A277: 64 | B277: 1 | C277: 1 | D277: 170 | E277: 227 | F277: 0 | G277: 2 | H277: 155 | I277: 0 | J277: 2 | K277: 7 | L277: 0 | M277: =IF(ClevelandData[[#This Row],[num]]=0,0,1) -> 0
A278: 66 | B278: 0 | C278: 3 | D278: 146 | E278: 278 | F278: 0 | G278: 2 | H278: 152 | I278: 0 | J278: 2 | K278: 3 | L278: 0 | M278: =IF(ClevelandData[[#This Row],[num]]=0,0,1) -> 0
A279: 39 | B279: 0 | C279: 3 | D279: 138 | E279: 220 | F279: 0 | G279: 0 | H279: 152 | I279: 0 | J279: 2 | K279: 3 | L279: 0 | M279: =IF(ClevelandData[[#This Row],[num]]=0,0,1) -> 0
...

Sheet analysis
B1: Averages
B2: Row Labels | C2: Average of age | D2: Average of rbp | E2: Average of maxhr | F2: Average of chol
B3: Female | C3: 55.721649 | D3: 133.34021 | E3: 151.2268 | F3: 261.75258
B4: No Heart Disease | C4: 54.555556 | D4: 128.73611 | E4: 154.02778 | F4: 256.75
B5: Heart Disease | C5: 59.08 | D5: 146.6 | E5: 143.16 | F5: 276.16
B6: Male | C6: 53.834951 | D6: 130.91262 | E6: 148.84466 | F6: 239.60194
B7: No Heart Disease | C7: 51.043478 | D7: 129.65217 | E7: 161.78261 | F7: 231.59783
B8: Heart Disease | C8: 56.087719 | D8: 131.92982 | E8: 138.40351 | F8: 246.0614
B9: Grand Total | C9: 54.438944 | D9: 131.68977 | E9: 149.60726 | F9: 246.69307
B12: Quick Overview
B13: Disease Status | C13: Patients | D13: % of patients
B14: No Heart Diease | C14: 164 | D14: 0.54125413
B15: Heart Disease | C15: 139 | D15: 0.45874587
B16: Grand Total | C16: 303 | D16: 1
B19: Correlation Matrix
B20: Variable | C20: Age | D20: Resting BP | E20: Cholesterol | F20: Max HR
B21: Age | C21: =CORREL(cleveland_data!A:A,cleveland_data!A:A) -> 1 | D21: =CORREL(cleveland_data!A:A,cleveland_data!D:D) -> 0.28494592 | E21: =CORREL(cleveland_data!A:A,cleveland_data!E:E) -> 0.20895027 | F21: =CORREL(cleveland_data!A:A,cleveland_data!H:H) -> -0.39380581
B22: Resting BP | C22: =CORREL(cleveland_data!D:D,cleveland_data!A:A) -> 0.28494592 | D22: =CORREL(cleveland_data!D:D,cleveland_data!D:D) -> 1 | E22: =CORREL(cleveland_data!D:D,cleveland_data!E:E) -> 0.13012011 | F22: =CORREL(cleveland_data!D:D,cleveland_data!H:H) -> -0.045350879
B23: Cholesterol | C23: =CORREL(cleveland_data!E:E,cleveland_data!A:A) -> 0.20895027 | D23: =CORREL(cleveland_data!E:E,cleveland_data!D:D) -> 0.13012011 | E23: =CORREL(cleveland_data!E:E,cleveland_data!E:E) -> 1 | F23: =CORREL(cleveland_data!E:E,cleveland_data!H:H) -> -0.0034318315
B24: Max HR | C24: =CORREL(cleveland_data!H:H,cleveland_data!A:A) -> -0.39380581 | D24: =CORREL(cleveland_data!H:H,cleveland_data!D:D) -> -0.045350879 | E24: =CORREL(cleveland_data!H:H,cleveland_data!E:E) -> -0.0034318315 | F24: =CORREL(cleveland_data!H:H,cleveland_data!H:H) -> 1
C27: Column Labels
C28: No Heart Disease | E28: Heart Disease
B29: Sex | C29: Patients | D29: % | E29: Patients | F29: %
B30: Female | C30: 72 | D30: 0.74226804 | E30: 25 | F30: 0.25773196
B31: Male | C31: 92 | D31: 0.44660194 | E31: 114 | F31: 0.55339806
B32: Grand Total | C32: 164 | D32: 0.54125413 | E32: 139 | F32: 0.45874587
B34: filter by sex | C34: (All)
C36: Column Labels
C37: No Heart Disease | E37: Heart Disease
B38: Age Group | C38: Patients | D38: % | E38: Patients | F38: %
B39: 29-38 | C39: 8 | D39: 0.72727273 | E39: 3 | F39: 0.27272727
B40: 39-48 | C40: 50 | D40: 0.70422535 | E40: 21 | F40: 0.29577465
B41: 49-58 | C41: 63 | D41: 0.54310345 | E41: 53 | F41: 0.45689655
B42: 59-68 | C42: 35 | D42: 0.38043478 | E42: 57 | F42: 0.61956522
B43: 69-78 | C43: 8 | D43: 0.61538462 | E43: 5 | F43: 0.38461538
B44: Grand Total | C44: 164 | D44: 0.54125413 | E44: 139 | F44: 0.45874587
C46: Column Labels
C47: No Heart Disease | E47: Heart Disease
B48: Chest Pain Type | C48: Patients | D48: % | E48: Patients | F48: %
B49: Typical Angina | C49: 16 | D49: 0.69565217 | E49: 7 | F49: 0.30434783
...

Sheet chart_data
A1: Resting BP | D1: Cholesterol | G1: Max HR | J1: Quick Overview
A2: No Heart Disease | B2: Heart Disease | D2: No Heart Disease | E2: Heart Disease | G2: No Heart Disease | H2: Heart Disease | J2: Disease Status | K2: % of patients
A3: {=_xlfn._xlws.FILTER(ClevelandData[rbp],ClevelandData[hd]=0)} -> 145 | B3: {=_xlfn._xlws.FILTER(ClevelandData[rbp],ClevelandData[hd]=1)} -> 160 | D3: {=_xlfn._xlws.FILTER(ClevelandData[chol],ClevelandData[hd]=0)} -> 233 | E3: {=_xlfn._xlws.FILTER(ClevelandData[chol],ClevelandData[hd]=1)} -> 286 | G3: {=_xlfn._xlws.FILTER(ClevelandData[maxhr],ClevelandData[hd]=0)} -> 150 | H3: {=_xlfn._xlws.FILTER(ClevelandData[maxhr],ClevelandData[hd]=1)} -> 108 | J3: No Heart Disease | K3: 0.54125413
A4: 130 | B4: 120 | D4: 250 | E4: 229 | G4: 187 | H4: 129 | J4: Heart Disease | K4: 0.45874587
A5: 130 | B5: 140 | D5: 204 | E5: 268 | G5: 172 | H5: 160 | J5: Grand Total | K5: 1
A6: 120 | B6: 130 | D6: 236 | E6: 254 | G6: 178 | H6: 147
A7: 120 | B7: 140 | D7: 354 | E7: 203 | G7: 163 | H7: 155 | J7: % of Patients | K7: Column Labels
A8: 140 | B8: 130 | D8: 192 | E8: 256 | G8: 148 | H8: 142 | J8: Sex | K8: No Heart Disease | L8: Heart Disease
A9: 140 | B9: 110 | D9: 294 | E9: 229 | G9: 153 | H9: 168 | J9: Female | K9: 0.74226804 | L9: 0.25773196
A10: 120 | B10: 120 | D10: 263 | E10: 284 | G10: 173 | H10: 160 | J10: Male | K10: 0.44660194 | L10: 0.55339806
A11: 172 | B11: 132 | D11: 199 | E11: 224 | G11: 162 | H11: 173 | J11: Grand Total | K11: 0.54125413 | L11: 0.45874587
A12: 150 | B12: 130 | D12: 168 | E12: 206 | G12: 174 | H12: 132
A13: 140 | B13: 110 | D13: 239 | E13: 167 | G13: 160 | H13: 114
A14: 130 | B14: 117 | D14: 275 | E14: 230 | G14: 139 | H14: 160 | J14: filter by sex | K14: (All)
A15: 130 | B15: 140 | D15: 266 | E15: 335 | G15: 171 | H15: 158
A16: 110 | B16: 120 | D16: 211 | E16: 177 | G16: 144 | H16: 120 | J16: % of Patients | K16: Column Labels
A17: 150 | B17: 150 | D17: 283 | E17: 276 | G17: 162 | H17: 112 | J17: Age Group | K17: No Heart Disease | L17: Heart Disease
A18: 120 | B18: 132 | D18: 219 | E18: 353 | G18: 158 | H18: 132 | J18: 29-38 | K18: 0.72727273 | L18: 0.27272727
A19: 120 | B19: 150 | D19: 340 | E19: 225 | G19: 172 | H19: 114 | J19: 39-48 | K19: 0.70422535 | L19: 0.29577465
A20: 150 | B20: 130 | D20: 226 | E20: 330 | G20: 114 | H20: 169 | J20: 49-58 | K20: 0.54310345 | L20: 0.45689655
A21: 150 | B21: 112 | D21: 247 | E21: 230 | G21: 171 | H21: 165 | J21: 59-68 | K21: 0.38043478 | L21: 0.61956522
A22: 140 | B22: 150 | D22: 239 | E22: 243 | G22: 151 | H22: 128 | J22: 69-78 | K22: 0.61538462 | L22: 0.38461538
A23: 135 | B23: 112 | D23: 234 | E23: 290 | G23: 161 | H23: 153 | J23: Grand Total | K23: 0.54125413 | L23: 0.45874587
A24: 130 | B24: 130 | D24: 233 | E24: 253 | G24: 179 | H24: 144
A25: 140 | B25: 124 | D25: 226 | E25: 266 | G25: 178 | H25: 109
A26: 150 | B26: 140 | D26: 243 | E26: 233 | G26: 137 | H26: 163 | J26: filter by age group | K26: (All)
A27: 140 | B27: 110 | D27: 199 | E27: 172 | G27: 178 | H27: 158 | J27: filter by sex | K27: (All)
A28: 160 | B28: 130 | D28: 302 | E28: 305 | G28: 162 | H28: 142
A29: 150 | B29: 128 | D29: 212 | E29: 216 | G29: 157 | H29: 131 | J29: % of Patients | K29: Column Labels
A30: 110 | B30: 120 | D30: 175 | E30: 188 | G30: 123 | H30: 113 | J30: Chest Pain Type | K30: No Heart Disease | L30: Heart Disease
A31: 140 | B31: 145 | D31: 417 | E31: 282 | G31: 157 | H31: 142 | J31: Typical Angina | K31: 0.69565217 | L31: 0.30434783
A32: 130 | B32: 140 | D32: 197 | E32: 185 | G32: 152 | H32: 155 | J32: Atypical Angina | K32: 0.82 | L32: 0.18
A33: 105 | B33: 170 | D33: 198 | E33: 326 | G33: 168 | H33: 140 | J33: Non-anginal | K33: 0.79069767 | L33: 0.20930233
A34: 120 | B34: 150 | D34: 177 | E34: 231 | G34: 140 | H34: 147 | J34: Asymptomatic | K34: 0.27083333 | L34: 0.72916667
A35: 130 | B35: 125 | D35: 219 | E35: 254 | G35: 188 | H35: 163 | J35: Grand Total | K35: 0.54125413 | L35: 0.45874587
A36: 125 | B36: 120 | D36: 273 | E36: 267 | G36: 152 | H36: 99
A37: 125 | B37: 110 | D37: 213 | E37: 248 | G37: 125 | H37: 158
A38: 142 | B38: 110 | D38: 177 | E38: 197 | G38: 160 | H38: 177 | J38: filter by age group | K38: (All)
A39: 135 | B39: 125 | D39: 304 | E39: 258 | G39: 170 | H39: 141 | J39: filter by sex | K39: (All)
A40: 150 | B40: 150 | D40: 232 | E40: 270 | G40: 165 | H40: 111 | J40: Heart Disease Status by Exercised-induced Angina Category
...

Sheet charts

Sheet dashboard
